ERROR 2025-07-21 18:35:20,625 log 15513 140446282012224 Invalid HTTP_HOST header: 'soju889.online'. You may need to add 'soju889.online' to ALLOWED_HOSTS.
Traceback (most recent call last):
  File "/opt/mcads/app/venv/lib/python3.10/site-packages/asgiref/sync.py", line 489, in thread_handler
    raise exc_info[1]
  File "/opt/mcads/app/venv/lib/python3.10/site-packages/django/core/handlers/exception.py", line 42, in inner
    response = await get_response(request)
  File "/opt/mcads/app/venv/lib/python3.10/site-packages/django/utils/deprecation.py", line 132, in __acall__
    response = await sync_to_async(
  File "/opt/mcads/app/venv/lib/python3.10/site-packages/asgiref/sync.py", line 439, in __call__
    ret = await asyncio.shield(exec_coro)
  File "/usr/lib/python3.10/concurrent/futures/thread.py", line 58, in run
    result = self.fn(*self.args, **self.kwargs)
  File "/opt/mcads/app/venv/lib/python3.10/site-packages/asgiref/sync.py", line 493, in thread_handler
    return func(*args, **kwargs)
  File "/opt/mcads/app/venv/lib/python3.10/site-packages/django/middleware/common.py", line 48, in process_request
    host = request.get_host()
  File "/opt/mcads/app/venv/lib/python3.10/site-packages/django/http/request.py", line 202, in get_host
    raise DisallowedHost(msg)
django.core.exceptions.DisallowedHost: Invalid HTTP_HOST header: 'soju889.online'. You may need to add 'soju889.online' to ALLOWED_HOSTS.
ERROR 2025-07-21 18:35:20,970 log 15513 140446256834112 Invalid HTTP_HOST header: 'soju889.online'. You may need to add 'soju889.online' to ALLOWED_HOSTS.
Traceback (most recent call last):
  File "/opt/mcads/app/venv/lib/python3.10/site-packages/asgiref/sync.py", line 489, in thread_handler
    raise exc_info[1]
  File "/opt/mcads/app/venv/lib/python3.10/site-packages/django/core/handlers/exception.py", line 42, in inner
    response = await get_response(request)
  File "/opt/mcads/app/venv/lib/python3.10/site-packages/django/utils/deprecation.py", line 132, in __acall__
    response = await sync_to_async(
  File "/opt/mcads/app/venv/lib/python3.10/site-packages/asgiref/sync.py", line 439, in __call__
    ret = await asyncio.shield(exec_coro)
  File "/usr/lib/python3.10/concurrent/futures/thread.py", line 58, in run
    result = self.fn(*self.args, **self.kwargs)
  File "/opt/mcads/app/venv/lib/python3.10/site-packages/asgiref/sync.py", line 493, in thread_handler
    return func(*args, **kwargs)
  File "/opt/mcads/app/venv/lib/python3.10/site-packages/django/middleware/common.py", line 48, in process_request
    host = request.get_host()
  File "/opt/mcads/app/venv/lib/python3.10/site-packages/django/http/request.py", line 202, in get_host
    raise DisallowedHost(msg)
django.core.exceptions.DisallowedHost: Invalid HTTP_HOST header: 'soju889.online'. You may need to add 'soju889.online' to ALLOWED_HOSTS.
ERROR 2025-07-21 18:35:21,350 log 15513 140446290404928 Invalid HTTP_HOST header: 'soju889.online'. You may need to add 'soju889.online' to ALLOWED_HOSTS.
Traceback (most recent call last):
  File "/opt/mcads/app/venv/lib/python3.10/site-packages/asgiref/sync.py", line 489, in thread_handler
    raise exc_info[1]
  File "/opt/mcads/app/venv/lib/python3.10/site-packages/django/core/handlers/exception.py", line 42, in inner
    response = await get_response(request)
  File "/opt/mcads/app/venv/lib/python3.10/site-packages/django/utils/deprecation.py", line 132, in __acall__
    response = await sync_to_async(
  File "/opt/mcads/app/venv/lib/python3.10/site-packages/asgiref/sync.py", line 439, in __call__
    ret = await asyncio.shield(exec_coro)
  File "/usr/lib/python3.10/concurrent/futures/thread.py", line 58, in run
    result = self.fn(*self.args, **self.kwargs)
  File "/opt/mcads/app/venv/lib/python3.10/site-packages/asgiref/sync.py", line 493, in thread_handler
    return func(*args, **kwargs)
  File "/opt/mcads/app/venv/lib/python3.10/site-packages/django/middleware/common.py", line 48, in process_request
    host = request.get_host()
  File "/opt/mcads/app/venv/lib/python3.10/site-packages/django/http/request.py", line 202, in get_host
    raise DisallowedHost(msg)
django.core.exceptions.DisallowedHost: Invalid HTTP_HOST header: 'soju889.online'. You may need to add 'soju889.online' to ALLOWED_HOSTS.
ERROR 2025-07-21 18:35:21,928 log 15513 140445749335616 Invalid HTTP_HOST header: 'soju889.online'. You may need to add 'soju889.online' to ALLOWED_HOSTS.
Traceback (most recent call last):
  File "/opt/mcads/app/venv/lib/python3.10/site-packages/asgiref/sync.py", line 489, in thread_handler
    raise exc_info[1]
  File "/opt/mcads/app/venv/lib/python3.10/site-packages/django/core/handlers/exception.py", line 42, in inner
    response = await get_response(request)
  File "/opt/mcads/app/venv/lib/python3.10/site-packages/django/utils/deprecation.py", line 132, in __acall__
    response = await sync_to_async(
  File "/opt/mcads/app/venv/lib/python3.10/site-packages/asgiref/sync.py", line 439, in __call__
    ret = await asyncio.shield(exec_coro)
  File "/usr/lib/python3.10/concurrent/futures/thread.py", line 58, in run
    result = self.fn(*self.args, **self.kwargs)
  File "/opt/mcads/app/venv/lib/python3.10/site-packages/asgiref/sync.py", line 493, in thread_handler
    return func(*args, **kwargs)
  File "/opt/mcads/app/venv/lib/python3.10/site-packages/django/middleware/common.py", line 48, in process_request
    host = request.get_host()
  File "/opt/mcads/app/venv/lib/python3.10/site-packages/django/http/request.py", line 202, in get_host
    raise DisallowedHost(msg)
django.core.exceptions.DisallowedHost: Invalid HTTP_HOST header: 'soju889.online'. You may need to add 'soju889.online' to ALLOWED_HOSTS.
ERROR 2025-07-21 18:35:22,127 log 15513 140446282012224 Invalid HTTP_HOST header: 'soju889.online'. You may need to add 'soju889.online' to ALLOWED_HOSTS.
Traceback (most recent call last):
  File "/opt/mcads/app/venv/lib/python3.10/site-packages/asgiref/sync.py", line 489, in thread_handler
    raise exc_info[1]
  File "/opt/mcads/app/venv/lib/python3.10/site-packages/django/core/handlers/exception.py", line 42, in inner
    response = await get_response(request)
  File "/opt/mcads/app/venv/lib/python3.10/site-packages/django/utils/deprecation.py", line 132, in __acall__
    response = await sync_to_async(
  File "/opt/mcads/app/venv/lib/python3.10/site-packages/asgiref/sync.py", line 439, in __call__
    ret = await asyncio.shield(exec_coro)
  File "/usr/lib/python3.10/concurrent/futures/thread.py", line 58, in run
    result = self.fn(*self.args, **self.kwargs)
  File "/opt/mcads/app/venv/lib/python3.10/site-packages/asgiref/sync.py", line 493, in thread_handler
    return func(*args, **kwargs)
  File "/opt/mcads/app/venv/lib/python3.10/site-packages/django/middleware/common.py", line 48, in process_request
    host = request.get_host()
  File "/opt/mcads/app/venv/lib/python3.10/site-packages/django/http/request.py", line 202, in get_host
    raise DisallowedHost(msg)
django.core.exceptions.DisallowedHost: Invalid HTTP_HOST header: 'soju889.online'. You may need to add 'soju889.online' to ALLOWED_HOSTS.
ERROR 2025-07-21 18:35:22,534 log 15513 140446290404928 Invalid HTTP_HOST header: 'soju889.online'. You may need to add 'soju889.online' to ALLOWED_HOSTS.
Traceback (most recent call last):
  File "/opt/mcads/app/venv/lib/python3.10/site-packages/asgiref/sync.py", line 489, in thread_handler
    raise exc_info[1]
  File "/opt/mcads/app/venv/lib/python3.10/site-packages/django/core/handlers/exception.py", line 42, in inner
    response = await get_response(request)
  File "/opt/mcads/app/venv/lib/python3.10/site-packages/django/utils/deprecation.py", line 132, in __acall__
    response = await sync_to_async(
  File "/opt/mcads/app/venv/lib/python3.10/site-packages/asgiref/sync.py", line 439, in __call__
    ret = await asyncio.shield(exec_coro)
  File "/usr/lib/python3.10/concurrent/futures/thread.py", line 58, in run
    result = self.fn(*self.args, **self.kwargs)
  File "/opt/mcads/app/venv/lib/python3.10/site-packages/asgiref/sync.py", line 493, in thread_handler
    return func(*args, **kwargs)
  File "/opt/mcads/app/venv/lib/python3.10/site-packages/django/middleware/common.py", line 48, in process_request
    host = request.get_host()
  File "/opt/mcads/app/venv/lib/python3.10/site-packages/django/http/request.py", line 202, in get_host
    raise DisallowedHost(msg)
django.core.exceptions.DisallowedHost: Invalid HTTP_HOST header: 'soju889.online'. You may need to add 'soju889.online' to ALLOWED_HOSTS.
ERROR 2025-07-21 18:35:23,096 log 15513 140446256834112 Invalid HTTP_HOST header: 'soju889.online'. You may need to add 'soju889.online' to ALLOWED_HOSTS.
Traceback (most recent call last):
  File "/opt/mcads/app/venv/lib/python3.10/site-packages/asgiref/sync.py", line 489, in thread_handler
    raise exc_info[1]
  File "/opt/mcads/app/venv/lib/python3.10/site-packages/django/core/handlers/exception.py", line 42, in inner
    response = await get_response(request)
  File "/opt/mcads/app/venv/lib/python3.10/site-packages/django/utils/deprecation.py", line 132, in __acall__
    response = await sync_to_async(
  File "/opt/mcads/app/venv/lib/python3.10/site-packages/asgiref/sync.py", line 439, in __call__
    ret = await asyncio.shield(exec_coro)
  File "/usr/lib/python3.10/concurrent/futures/thread.py", line 58, in run
    result = self.fn(*self.args, **self.kwargs)
  File "/opt/mcads/app/venv/lib/python3.10/site-packages/asgiref/sync.py", line 493, in thread_handler
    return func(*args, **kwargs)
  File "/opt/mcads/app/venv/lib/python3.10/site-packages/django/middleware/common.py", line 48, in process_request
    host = request.get_host()
  File "/opt/mcads/app/venv/lib/python3.10/site-packages/django/http/request.py", line 202, in get_host
    raise DisallowedHost(msg)
django.core.exceptions.DisallowedHost: Invalid HTTP_HOST header: 'soju889.online'. You may need to add 'soju889.online' to ALLOWED_HOSTS.
ERROR 2025-07-21 18:35:23,470 log 15513 140446282012224 Invalid HTTP_HOST header: 'soju889.online'. You may need to add 'soju889.online' to ALLOWED_HOSTS.
Traceback (most recent call last):
  File "/opt/mcads/app/venv/lib/python3.10/site-packages/asgiref/sync.py", line 489, in thread_handler
    raise exc_info[1]
  File "/opt/mcads/app/venv/lib/python3.10/site-packages/django/core/handlers/exception.py", line 42, in inner
    response = await get_response(request)
  File "/opt/mcads/app/venv/lib/python3.10/site-packages/django/utils/deprecation.py", line 132, in __acall__
    response = await sync_to_async(
  File "/opt/mcads/app/venv/lib/python3.10/site-packages/asgiref/sync.py", line 439, in __call__
    ret = await asyncio.shield(exec_coro)
  File "/usr/lib/python3.10/concurrent/futures/thread.py", line 58, in run
    result = self.fn(*self.args, **self.kwargs)
  File "/opt/mcads/app/venv/lib/python3.10/site-packages/asgiref/sync.py", line 493, in thread_handler
    return func(*args, **kwargs)
  File "/opt/mcads/app/venv/lib/python3.10/site-packages/django/middleware/common.py", line 48, in process_request
    host = request.get_host()
  File "/opt/mcads/app/venv/lib/python3.10/site-packages/django/http/request.py", line 202, in get_host
    raise DisallowedHost(msg)
django.core.exceptions.DisallowedHost: Invalid HTTP_HOST header: 'soju889.online'. You may need to add 'soju889.online' to ALLOWED_HOSTS.
ERROR 2025-07-21 18:35:24,018 log 15513 140445749335616 Invalid HTTP_HOST header: 'soju889.online'. You may need to add 'soju889.online' to ALLOWED_HOSTS.
Traceback (most recent call last):
  File "/opt/mcads/app/venv/lib/python3.10/site-packages/asgiref/sync.py", line 489, in thread_handler
    raise exc_info[1]
  File "/opt/mcads/app/venv/lib/python3.10/site-packages/django/core/handlers/exception.py", line 42, in inner
    response = await get_response(request)
  File "/opt/mcads/app/venv/lib/python3.10/site-packages/django/utils/deprecation.py", line 132, in __acall__
    response = await sync_to_async(
  File "/opt/mcads/app/venv/lib/python3.10/site-packages/asgiref/sync.py", line 439, in __call__
    ret = await asyncio.shield(exec_coro)
  File "/usr/lib/python3.10/concurrent/futures/thread.py", line 58, in run
    result = self.fn(*self.args, **self.kwargs)
  File "/opt/mcads/app/venv/lib/python3.10/site-packages/asgiref/sync.py", line 493, in thread_handler
    return func(*args, **kwargs)
  File "/opt/mcads/app/venv/lib/python3.10/site-packages/django/middleware/common.py", line 48, in process_request
    host = request.get_host()
  File "/opt/mcads/app/venv/lib/python3.10/site-packages/django/http/request.py", line 202, in get_host
    raise DisallowedHost(msg)
django.core.exceptions.DisallowedHost: Invalid HTTP_HOST header: 'soju889.online'. You may need to add 'soju889.online' to ALLOWED_HOSTS.
ERROR 2025-07-21 18:35:24,392 log 15513 140446290404928 Invalid HTTP_HOST header: 'soju889.online'. You may need to add 'soju889.online' to ALLOWED_HOSTS.
Traceback (most recent call last):
  File "/opt/mcads/app/venv/lib/python3.10/site-packages/asgiref/sync.py", line 489, in thread_handler
    raise exc_info[1]
  File "/opt/mcads/app/venv/lib/python3.10/site-packages/django/core/handlers/exception.py", line 42, in inner
    response = await get_response(request)
  File "/opt/mcads/app/venv/lib/python3.10/site-packages/django/utils/deprecation.py", line 132, in __acall__
    response = await sync_to_async(
  File "/opt/mcads/app/venv/lib/python3.10/site-packages/asgiref/sync.py", line 439, in __call__
    ret = await asyncio.shield(exec_coro)
  File "/usr/lib/python3.10/concurrent/futures/thread.py", line 58, in run
    result = self.fn(*self.args, **self.kwargs)
  File "/opt/mcads/app/venv/lib/python3.10/site-packages/asgiref/sync.py", line 493, in thread_handler
    return func(*args, **kwargs)
  File "/opt/mcads/app/venv/lib/python3.10/site-packages/django/middleware/common.py", line 48, in process_request
    host = request.get_host()
  File "/opt/mcads/app/venv/lib/python3.10/site-packages/django/http/request.py", line 202, in get_host
    raise DisallowedHost(msg)
django.core.exceptions.DisallowedHost: Invalid HTTP_HOST header: 'soju889.online'. You may need to add 'soju889.online' to ALLOWED_HOSTS.
ERROR 2025-07-21 18:35:31,985 log 15513 140446256834112 Invalid HTTP_HOST header: 'topan4dd.site'. You may need to add 'topan4dd.site' to ALLOWED_HOSTS.
Traceback (most recent call last):
  File "/opt/mcads/app/venv/lib/python3.10/site-packages/asgiref/sync.py", line 489, in thread_handler
    raise exc_info[1]
  File "/opt/mcads/app/venv/lib/python3.10/site-packages/django/core/handlers/exception.py", line 42, in inner
    response = await get_response(request)
  File "/opt/mcads/app/venv/lib/python3.10/site-packages/django/utils/deprecation.py", line 132, in __acall__
    response = await sync_to_async(
  File "/opt/mcads/app/venv/lib/python3.10/site-packages/asgiref/sync.py", line 439, in __call__
    ret = await asyncio.shield(exec_coro)
  File "/usr/lib/python3.10/concurrent/futures/thread.py", line 58, in run
    result = self.fn(*self.args, **self.kwargs)
  File "/opt/mcads/app/venv/lib/python3.10/site-packages/asgiref/sync.py", line 493, in thread_handler
    return func(*args, **kwargs)
  File "/opt/mcads/app/venv/lib/python3.10/site-packages/django/middleware/common.py", line 48, in process_request
    host = request.get_host()
  File "/opt/mcads/app/venv/lib/python3.10/site-packages/django/http/request.py", line 202, in get_host
    raise DisallowedHost(msg)
django.core.exceptions.DisallowedHost: Invalid HTTP_HOST header: 'topan4dd.site'. You may need to add 'topan4dd.site' to ALLOWED_HOSTS.
ERROR 2025-07-21 18:35:35,019 log 15513 140445749335616 Invalid HTTP_HOST header: 'topan4dd.site'. You may need to add 'topan4dd.site' to ALLOWED_HOSTS.
Traceback (most recent call last):
  File "/opt/mcads/app/venv/lib/python3.10/site-packages/asgiref/sync.py", line 489, in thread_handler
    raise exc_info[1]
  File "/opt/mcads/app/venv/lib/python3.10/site-packages/django/core/handlers/exception.py", line 42, in inner
    response = await get_response(request)
  File "/opt/mcads/app/venv/lib/python3.10/site-packages/django/utils/deprecation.py", line 132, in __acall__
    response = await sync_to_async(
  File "/opt/mcads/app/venv/lib/python3.10/site-packages/asgiref/sync.py", line 439, in __call__
    ret = await asyncio.shield(exec_coro)
  File "/usr/lib/python3.10/concurrent/futures/thread.py", line 58, in run
    result = self.fn(*self.args, **self.kwargs)
  File "/opt/mcads/app/venv/lib/python3.10/site-packages/asgiref/sync.py", line 493, in thread_handler
    return func(*args, **kwargs)
  File "/opt/mcads/app/venv/lib/python3.10/site-packages/django/middleware/common.py", line 48, in process_request
    host = request.get_host()
  File "/opt/mcads/app/venv/lib/python3.10/site-packages/django/http/request.py", line 202, in get_host
    raise DisallowedHost(msg)
django.core.exceptions.DisallowedHost: Invalid HTTP_HOST header: 'topan4dd.site'. You may need to add 'topan4dd.site' to ALLOWED_HOSTS.
ERROR 2025-07-21 18:39:14,847 log 15513 140446282012224 Invalid HTTP_HOST header: 'hvacprofitmastery.com'. You may need to add 'hvacprofitmastery.com' to ALLOWED_HOSTS.
Traceback (most recent call last):
  File "/opt/mcads/app/venv/lib/python3.10/site-packages/asgiref/sync.py", line 489, in thread_handler
    raise exc_info[1]
  File "/opt/mcads/app/venv/lib/python3.10/site-packages/django/core/handlers/exception.py", line 42, in inner
    response = await get_response(request)
  File "/opt/mcads/app/venv/lib/python3.10/site-packages/django/utils/deprecation.py", line 132, in __acall__
    response = await sync_to_async(
  File "/opt/mcads/app/venv/lib/python3.10/site-packages/asgiref/sync.py", line 439, in __call__
    ret = await asyncio.shield(exec_coro)
  File "/usr/lib/python3.10/concurrent/futures/thread.py", line 58, in run
    result = self.fn(*self.args, **self.kwargs)
  File "/opt/mcads/app/venv/lib/python3.10/site-packages/asgiref/sync.py", line 493, in thread_handler
    return func(*args, **kwargs)
  File "/opt/mcads/app/venv/lib/python3.10/site-packages/django/middleware/common.py", line 48, in process_request
    host = request.get_host()
  File "/opt/mcads/app/venv/lib/python3.10/site-packages/django/http/request.py", line 202, in get_host
    raise DisallowedHost(msg)
django.core.exceptions.DisallowedHost: Invalid HTTP_HOST header: 'hvacprofitmastery.com'. You may need to add 'hvacprofitmastery.com' to ALLOWED_HOSTS.
ERROR 2025-07-21 18:39:16,388 log 15513 140446256834112 Invalid HTTP_HOST header: 'hvacprofitmastery.com'. You may need to add 'hvacprofitmastery.com' to ALLOWED_HOSTS.
Traceback (most recent call last):
  File "/opt/mcads/app/venv/lib/python3.10/site-packages/asgiref/sync.py", line 489, in thread_handler
    raise exc_info[1]
  File "/opt/mcads/app/venv/lib/python3.10/site-packages/django/core/handlers/exception.py", line 42, in inner
    response = await get_response(request)
  File "/opt/mcads/app/venv/lib/python3.10/site-packages/django/utils/deprecation.py", line 132, in __acall__
    response = await sync_to_async(
  File "/opt/mcads/app/venv/lib/python3.10/site-packages/asgiref/sync.py", line 439, in __call__
    ret = await asyncio.shield(exec_coro)
  File "/usr/lib/python3.10/concurrent/futures/thread.py", line 58, in run
    result = self.fn(*self.args, **self.kwargs)
  File "/opt/mcads/app/venv/lib/python3.10/site-packages/asgiref/sync.py", line 493, in thread_handler
    return func(*args, **kwargs)
  File "/opt/mcads/app/venv/lib/python3.10/site-packages/django/middleware/common.py", line 48, in process_request
    host = request.get_host()
  File "/opt/mcads/app/venv/lib/python3.10/site-packages/django/http/request.py", line 202, in get_host
    raise DisallowedHost(msg)
django.core.exceptions.DisallowedHost: Invalid HTTP_HOST header: 'hvacprofitmastery.com'. You may need to add 'hvacprofitmastery.com' to ALLOWED_HOSTS.
ERROR 2025-07-21 18:41:30,397 log 15513 140446290404928 Invalid HTTP_HOST header: 'topan4dd.site'. You may need to add 'topan4dd.site' to ALLOWED_HOSTS.
Traceback (most recent call last):
  File "/opt/mcads/app/venv/lib/python3.10/site-packages/asgiref/sync.py", line 489, in thread_handler
    raise exc_info[1]
  File "/opt/mcads/app/venv/lib/python3.10/site-packages/django/core/handlers/exception.py", line 42, in inner
    response = await get_response(request)
  File "/opt/mcads/app/venv/lib/python3.10/site-packages/django/utils/deprecation.py", line 132, in __acall__
    response = await sync_to_async(
  File "/opt/mcads/app/venv/lib/python3.10/site-packages/asgiref/sync.py", line 439, in __call__
    ret = await asyncio.shield(exec_coro)
  File "/usr/lib/python3.10/concurrent/futures/thread.py", line 58, in run
    result = self.fn(*self.args, **self.kwargs)
  File "/opt/mcads/app/venv/lib/python3.10/site-packages/asgiref/sync.py", line 493, in thread_handler
    return func(*args, **kwargs)
  File "/opt/mcads/app/venv/lib/python3.10/site-packages/django/middleware/common.py", line 48, in process_request
    host = request.get_host()
  File "/opt/mcads/app/venv/lib/python3.10/site-packages/django/http/request.py", line 202, in get_host
    raise DisallowedHost(msg)
django.core.exceptions.DisallowedHost: Invalid HTTP_HOST header: 'topan4dd.site'. You may need to add 'topan4dd.site' to ALLOWED_HOSTS.
ERROR 2025-07-21 18:42:05,215 log 15513 140446282012224 Invalid HTTP_HOST header: 'apek88.store'. You may need to add 'apek88.store' to ALLOWED_HOSTS.
Traceback (most recent call last):
  File "/opt/mcads/app/venv/lib/python3.10/site-packages/asgiref/sync.py", line 489, in thread_handler
    raise exc_info[1]
  File "/opt/mcads/app/venv/lib/python3.10/site-packages/django/core/handlers/exception.py", line 42, in inner
    response = await get_response(request)
  File "/opt/mcads/app/venv/lib/python3.10/site-packages/django/utils/deprecation.py", line 132, in __acall__
    response = await sync_to_async(
  File "/opt/mcads/app/venv/lib/python3.10/site-packages/asgiref/sync.py", line 439, in __call__
    ret = await asyncio.shield(exec_coro)
  File "/usr/lib/python3.10/concurrent/futures/thread.py", line 58, in run
    result = self.fn(*self.args, **self.kwargs)
  File "/opt/mcads/app/venv/lib/python3.10/site-packages/asgiref/sync.py", line 493, in thread_handler
    return func(*args, **kwargs)
  File "/opt/mcads/app/venv/lib/python3.10/site-packages/django/middleware/common.py", line 48, in process_request
    host = request.get_host()
  File "/opt/mcads/app/venv/lib/python3.10/site-packages/django/http/request.py", line 202, in get_host
    raise DisallowedHost(msg)
django.core.exceptions.DisallowedHost: Invalid HTTP_HOST header: 'apek88.store'. You may need to add 'apek88.store' to ALLOWED_HOSTS.
ERROR 2025-07-21 18:42:06,111 log 15513 140445749335616 Invalid HTTP_HOST header: 'apek88.store'. You may need to add 'apek88.store' to ALLOWED_HOSTS.
Traceback (most recent call last):
  File "/opt/mcads/app/venv/lib/python3.10/site-packages/asgiref/sync.py", line 489, in thread_handler
    raise exc_info[1]
  File "/opt/mcads/app/venv/lib/python3.10/site-packages/django/core/handlers/exception.py", line 42, in inner
    response = await get_response(request)
  File "/opt/mcads/app/venv/lib/python3.10/site-packages/django/utils/deprecation.py", line 132, in __acall__
    response = await sync_to_async(
  File "/opt/mcads/app/venv/lib/python3.10/site-packages/asgiref/sync.py", line 439, in __call__
    ret = await asyncio.shield(exec_coro)
  File "/usr/lib/python3.10/concurrent/futures/thread.py", line 58, in run
    result = self.fn(*self.args, **self.kwargs)
  File "/opt/mcads/app/venv/lib/python3.10/site-packages/asgiref/sync.py", line 493, in thread_handler
    return func(*args, **kwargs)
  File "/opt/mcads/app/venv/lib/python3.10/site-packages/django/middleware/common.py", line 48, in process_request
    host = request.get_host()
  File "/opt/mcads/app/venv/lib/python3.10/site-packages/django/http/request.py", line 202, in get_host
    raise DisallowedHost(msg)
django.core.exceptions.DisallowedHost: Invalid HTTP_HOST header: 'apek88.store'. You may need to add 'apek88.store' to ALLOWED_HOSTS.
ERROR 2025-07-21 18:42:06,311 log 15513 140446256834112 Invalid HTTP_HOST header: 'apek88.store'. You may need to add 'apek88.store' to ALLOWED_HOSTS.
Traceback (most recent call last):
  File "/opt/mcads/app/venv/lib/python3.10/site-packages/asgiref/sync.py", line 489, in thread_handler
    raise exc_info[1]
  File "/opt/mcads/app/venv/lib/python3.10/site-packages/django/core/handlers/exception.py", line 42, in inner
    response = await get_response(request)
  File "/opt/mcads/app/venv/lib/python3.10/site-packages/django/utils/deprecation.py", line 132, in __acall__
    response = await sync_to_async(
  File "/opt/mcads/app/venv/lib/python3.10/site-packages/asgiref/sync.py", line 439, in __call__
    ret = await asyncio.shield(exec_coro)
  File "/usr/lib/python3.10/concurrent/futures/thread.py", line 58, in run
    result = self.fn(*self.args, **self.kwargs)
  File "/opt/mcads/app/venv/lib/python3.10/site-packages/asgiref/sync.py", line 493, in thread_handler
    return func(*args, **kwargs)
  File "/opt/mcads/app/venv/lib/python3.10/site-packages/django/middleware/common.py", line 48, in process_request
    host = request.get_host()
  File "/opt/mcads/app/venv/lib/python3.10/site-packages/django/http/request.py", line 202, in get_host
    raise DisallowedHost(msg)
django.core.exceptions.DisallowedHost: Invalid HTTP_HOST header: 'apek88.store'. You may need to add 'apek88.store' to ALLOWED_HOSTS.
ERROR 2025-07-21 18:42:06,708 log 15513 140446282012224 Invalid HTTP_HOST header: 'apek88.store'. You may need to add 'apek88.store' to ALLOWED_HOSTS.
Traceback (most recent call last):
  File "/opt/mcads/app/venv/lib/python3.10/site-packages/asgiref/sync.py", line 489, in thread_handler
    raise exc_info[1]
  File "/opt/mcads/app/venv/lib/python3.10/site-packages/django/core/handlers/exception.py", line 42, in inner
    response = await get_response(request)
  File "/opt/mcads/app/venv/lib/python3.10/site-packages/django/utils/deprecation.py", line 132, in __acall__
    response = await sync_to_async(
  File "/opt/mcads/app/venv/lib/python3.10/site-packages/asgiref/sync.py", line 439, in __call__
    ret = await asyncio.shield(exec_coro)
  File "/usr/lib/python3.10/concurrent/futures/thread.py", line 58, in run
    result = self.fn(*self.args, **self.kwargs)
  File "/opt/mcads/app/venv/lib/python3.10/site-packages/asgiref/sync.py", line 493, in thread_handler
    return func(*args, **kwargs)
  File "/opt/mcads/app/venv/lib/python3.10/site-packages/django/middleware/common.py", line 48, in process_request
    host = request.get_host()
  File "/opt/mcads/app/venv/lib/python3.10/site-packages/django/http/request.py", line 202, in get_host
    raise DisallowedHost(msg)
django.core.exceptions.DisallowedHost: Invalid HTTP_HOST header: 'apek88.store'. You may need to add 'apek88.store' to ALLOWED_HOSTS.
ERROR 2025-07-21 18:42:06,907 log 15513 140446290404928 Invalid HTTP_HOST header: 'apek88.store'. You may need to add 'apek88.store' to ALLOWED_HOSTS.
Traceback (most recent call last):
  File "/opt/mcads/app/venv/lib/python3.10/site-packages/asgiref/sync.py", line 489, in thread_handler
    raise exc_info[1]
  File "/opt/mcads/app/venv/lib/python3.10/site-packages/django/core/handlers/exception.py", line 42, in inner
    response = await get_response(request)
  File "/opt/mcads/app/venv/lib/python3.10/site-packages/django/utils/deprecation.py", line 132, in __acall__
    response = await sync_to_async(
  File "/opt/mcads/app/venv/lib/python3.10/site-packages/asgiref/sync.py", line 439, in __call__
    ret = await asyncio.shield(exec_coro)
  File "/usr/lib/python3.10/concurrent/futures/thread.py", line 58, in run
    result = self.fn(*self.args, **self.kwargs)
  File "/opt/mcads/app/venv/lib/python3.10/site-packages/asgiref/sync.py", line 493, in thread_handler
    return func(*args, **kwargs)
  File "/opt/mcads/app/venv/lib/python3.10/site-packages/django/middleware/common.py", line 48, in process_request
    host = request.get_host()
  File "/opt/mcads/app/venv/lib/python3.10/site-packages/django/http/request.py", line 202, in get_host
    raise DisallowedHost(msg)
django.core.exceptions.DisallowedHost: Invalid HTTP_HOST header: 'apek88.store'. You may need to add 'apek88.store' to ALLOWED_HOSTS.
ERROR 2025-07-21 18:42:07,563 log 15513 140445749335616 Invalid HTTP_HOST header: 'apek88.store'. You may need to add 'apek88.store' to ALLOWED_HOSTS.
Traceback (most recent call last):
  File "/opt/mcads/app/venv/lib/python3.10/site-packages/asgiref/sync.py", line 489, in thread_handler
    raise exc_info[1]
  File "/opt/mcads/app/venv/lib/python3.10/site-packages/django/core/handlers/exception.py", line 42, in inner
    response = await get_response(request)
  File "/opt/mcads/app/venv/lib/python3.10/site-packages/django/utils/deprecation.py", line 132, in __acall__
    response = await sync_to_async(
  File "/opt/mcads/app/venv/lib/python3.10/site-packages/asgiref/sync.py", line 439, in __call__
    ret = await asyncio.shield(exec_coro)
  File "/usr/lib/python3.10/concurrent/futures/thread.py", line 58, in run
    result = self.fn(*self.args, **self.kwargs)
  File "/opt/mcads/app/venv/lib/python3.10/site-packages/asgiref/sync.py", line 493, in thread_handler
    return func(*args, **kwargs)
  File "/opt/mcads/app/venv/lib/python3.10/site-packages/django/middleware/common.py", line 48, in process_request
    host = request.get_host()
  File "/opt/mcads/app/venv/lib/python3.10/site-packages/django/http/request.py", line 202, in get_host
    raise DisallowedHost(msg)
django.core.exceptions.DisallowedHost: Invalid HTTP_HOST header: 'apek88.store'. You may need to add 'apek88.store' to ALLOWED_HOSTS.
ERROR 2025-07-21 18:42:08,050 log 15513 140446256834112 Invalid HTTP_HOST header: 'apek88.store'. You may need to add 'apek88.store' to ALLOWED_HOSTS.
Traceback (most recent call last):
  File "/opt/mcads/app/venv/lib/python3.10/site-packages/asgiref/sync.py", line 489, in thread_handler
    raise exc_info[1]
  File "/opt/mcads/app/venv/lib/python3.10/site-packages/django/core/handlers/exception.py", line 42, in inner
    response = await get_response(request)
  File "/opt/mcads/app/venv/lib/python3.10/site-packages/django/utils/deprecation.py", line 132, in __acall__
    response = await sync_to_async(
  File "/opt/mcads/app/venv/lib/python3.10/site-packages/asgiref/sync.py", line 439, in __call__
    ret = await asyncio.shield(exec_coro)
  File "/usr/lib/python3.10/concurrent/futures/thread.py", line 58, in run
    result = self.fn(*self.args, **self.kwargs)
  File "/opt/mcads/app/venv/lib/python3.10/site-packages/asgiref/sync.py", line 493, in thread_handler
    return func(*args, **kwargs)
  File "/opt/mcads/app/venv/lib/python3.10/site-packages/django/middleware/common.py", line 48, in process_request
    host = request.get_host()
  File "/opt/mcads/app/venv/lib/python3.10/site-packages/django/http/request.py", line 202, in get_host
    raise DisallowedHost(msg)
django.core.exceptions.DisallowedHost: Invalid HTTP_HOST header: 'apek88.store'. You may need to add 'apek88.store' to ALLOWED_HOSTS.
ERROR 2025-07-21 18:42:08,251 log 15513 140446282012224 Invalid HTTP_HOST header: 'apek88.store'. You may need to add 'apek88.store' to ALLOWED_HOSTS.
Traceback (most recent call last):
  File "/opt/mcads/app/venv/lib/python3.10/site-packages/asgiref/sync.py", line 489, in thread_handler
    raise exc_info[1]
  File "/opt/mcads/app/venv/lib/python3.10/site-packages/django/core/handlers/exception.py", line 42, in inner
    response = await get_response(request)
  File "/opt/mcads/app/venv/lib/python3.10/site-packages/django/utils/deprecation.py", line 132, in __acall__
    response = await sync_to_async(
  File "/opt/mcads/app/venv/lib/python3.10/site-packages/asgiref/sync.py", line 439, in __call__
    ret = await asyncio.shield(exec_coro)
  File "/usr/lib/python3.10/concurrent/futures/thread.py", line 58, in run
    result = self.fn(*self.args, **self.kwargs)
  File "/opt/mcads/app/venv/lib/python3.10/site-packages/asgiref/sync.py", line 493, in thread_handler
    return func(*args, **kwargs)
  File "/opt/mcads/app/venv/lib/python3.10/site-packages/django/middleware/common.py", line 48, in process_request
    host = request.get_host()
  File "/opt/mcads/app/venv/lib/python3.10/site-packages/django/http/request.py", line 202, in get_host
    raise DisallowedHost(msg)
django.core.exceptions.DisallowedHost: Invalid HTTP_HOST header: 'apek88.store'. You may need to add 'apek88.store' to ALLOWED_HOSTS.
ERROR 2025-07-21 18:42:08,660 log 15513 140446290404928 Invalid HTTP_HOST header: 'apek88.store'. You may need to add 'apek88.store' to ALLOWED_HOSTS.
Traceback (most recent call last):
  File "/opt/mcads/app/venv/lib/python3.10/site-packages/asgiref/sync.py", line 489, in thread_handler
    raise exc_info[1]
  File "/opt/mcads/app/venv/lib/python3.10/site-packages/django/core/handlers/exception.py", line 42, in inner
    response = await get_response(request)
  File "/opt/mcads/app/venv/lib/python3.10/site-packages/django/utils/deprecation.py", line 132, in __acall__
    response = await sync_to_async(
  File "/opt/mcads/app/venv/lib/python3.10/site-packages/asgiref/sync.py", line 439, in __call__
    ret = await asyncio.shield(exec_coro)
  File "/usr/lib/python3.10/concurrent/futures/thread.py", line 58, in run
    result = self.fn(*self.args, **self.kwargs)
  File "/opt/mcads/app/venv/lib/python3.10/site-packages/asgiref/sync.py", line 493, in thread_handler
    return func(*args, **kwargs)
  File "/opt/mcads/app/venv/lib/python3.10/site-packages/django/middleware/common.py", line 48, in process_request
    host = request.get_host()
  File "/opt/mcads/app/venv/lib/python3.10/site-packages/django/http/request.py", line 202, in get_host
    raise DisallowedHost(msg)
django.core.exceptions.DisallowedHost: Invalid HTTP_HOST header: 'apek88.store'. You may need to add 'apek88.store' to ALLOWED_HOSTS.
ERROR 2025-07-21 18:42:09,071 log 15513 140445749335616 Invalid HTTP_HOST header: 'apek88.store'. You may need to add 'apek88.store' to ALLOWED_HOSTS.
Traceback (most recent call last):
  File "/opt/mcads/app/venv/lib/python3.10/site-packages/asgiref/sync.py", line 489, in thread_handler
    raise exc_info[1]
  File "/opt/mcads/app/venv/lib/python3.10/site-packages/django/core/handlers/exception.py", line 42, in inner
    response = await get_response(request)
  File "/opt/mcads/app/venv/lib/python3.10/site-packages/django/utils/deprecation.py", line 132, in __acall__
    response = await sync_to_async(
  File "/opt/mcads/app/venv/lib/python3.10/site-packages/asgiref/sync.py", line 439, in __call__
    ret = await asyncio.shield(exec_coro)
  File "/usr/lib/python3.10/concurrent/futures/thread.py", line 58, in run
    result = self.fn(*self.args, **self.kwargs)
  File "/opt/mcads/app/venv/lib/python3.10/site-packages/asgiref/sync.py", line 493, in thread_handler
    return func(*args, **kwargs)
  File "/opt/mcads/app/venv/lib/python3.10/site-packages/django/middleware/common.py", line 48, in process_request
    host = request.get_host()
  File "/opt/mcads/app/venv/lib/python3.10/site-packages/django/http/request.py", line 202, in get_host
    raise DisallowedHost(msg)
django.core.exceptions.DisallowedHost: Invalid HTTP_HOST header: 'apek88.store'. You may need to add 'apek88.store' to ALLOWED_HOSTS.
ERROR 2025-07-21 18:42:09,286 log 15513 140446256834112 Invalid HTTP_HOST header: 'apek88.store'. You may need to add 'apek88.store' to ALLOWED_HOSTS.
Traceback (most recent call last):
  File "/opt/mcads/app/venv/lib/python3.10/site-packages/asgiref/sync.py", line 489, in thread_handler
    raise exc_info[1]
  File "/opt/mcads/app/venv/lib/python3.10/site-packages/django/core/handlers/exception.py", line 42, in inner
    response = await get_response(request)
  File "/opt/mcads/app/venv/lib/python3.10/site-packages/django/utils/deprecation.py", line 132, in __acall__
    response = await sync_to_async(
  File "/opt/mcads/app/venv/lib/python3.10/site-packages/asgiref/sync.py", line 439, in __call__
    ret = await asyncio.shield(exec_coro)
  File "/usr/lib/python3.10/concurrent/futures/thread.py", line 58, in run
    result = self.fn(*self.args, **self.kwargs)
  File "/opt/mcads/app/venv/lib/python3.10/site-packages/asgiref/sync.py", line 493, in thread_handler
    return func(*args, **kwargs)
  File "/opt/mcads/app/venv/lib/python3.10/site-packages/django/middleware/common.py", line 48, in process_request
    host = request.get_host()
  File "/opt/mcads/app/venv/lib/python3.10/site-packages/django/http/request.py", line 202, in get_host
    raise DisallowedHost(msg)
django.core.exceptions.DisallowedHost: Invalid HTTP_HOST header: 'apek88.store'. You may need to add 'apek88.store' to ALLOWED_HOSTS.
ERROR 2025-07-21 18:42:09,885 log 15513 140446282012224 Invalid HTTP_HOST header: 'apek88.store'. You may need to add 'apek88.store' to ALLOWED_HOSTS.
Traceback (most recent call last):
  File "/opt/mcads/app/venv/lib/python3.10/site-packages/asgiref/sync.py", line 489, in thread_handler
    raise exc_info[1]
  File "/opt/mcads/app/venv/lib/python3.10/site-packages/django/core/handlers/exception.py", line 42, in inner
    response = await get_response(request)
  File "/opt/mcads/app/venv/lib/python3.10/site-packages/django/utils/deprecation.py", line 132, in __acall__
    response = await sync_to_async(
  File "/opt/mcads/app/venv/lib/python3.10/site-packages/asgiref/sync.py", line 439, in __call__
    ret = await asyncio.shield(exec_coro)
  File "/usr/lib/python3.10/concurrent/futures/thread.py", line 58, in run
    result = self.fn(*self.args, **self.kwargs)
  File "/opt/mcads/app/venv/lib/python3.10/site-packages/asgiref/sync.py", line 493, in thread_handler
    return func(*args, **kwargs)
  File "/opt/mcads/app/venv/lib/python3.10/site-packages/django/middleware/common.py", line 48, in process_request
    host = request.get_host()
  File "/opt/mcads/app/venv/lib/python3.10/site-packages/django/http/request.py", line 202, in get_host
    raise DisallowedHost(msg)
django.core.exceptions.DisallowedHost: Invalid HTTP_HOST header: 'apek88.store'. You may need to add 'apek88.store' to ALLOWED_HOSTS.
ERROR 2025-07-21 18:42:10,483 log 15513 140445749335616 Invalid HTTP_HOST header: 'apek88.store'. You may need to add 'apek88.store' to ALLOWED_HOSTS.
Traceback (most recent call last):
  File "/opt/mcads/app/venv/lib/python3.10/site-packages/asgiref/sync.py", line 489, in thread_handler
    raise exc_info[1]
  File "/opt/mcads/app/venv/lib/python3.10/site-packages/django/core/handlers/exception.py", line 42, in inner
    response = await get_response(request)
  File "/opt/mcads/app/venv/lib/python3.10/site-packages/django/utils/deprecation.py", line 132, in __acall__
    response = await sync_to_async(
  File "/opt/mcads/app/venv/lib/python3.10/site-packages/asgiref/sync.py", line 439, in __call__
    ret = await asyncio.shield(exec_coro)
  File "/usr/lib/python3.10/concurrent/futures/thread.py", line 58, in run
    result = self.fn(*self.args, **self.kwargs)
  File "/opt/mcads/app/venv/lib/python3.10/site-packages/asgiref/sync.py", line 493, in thread_handler
    return func(*args, **kwargs)
  File "/opt/mcads/app/venv/lib/python3.10/site-packages/django/middleware/common.py", line 48, in process_request
    host = request.get_host()
  File "/opt/mcads/app/venv/lib/python3.10/site-packages/django/http/request.py", line 202, in get_host
    raise DisallowedHost(msg)
django.core.exceptions.DisallowedHost: Invalid HTTP_HOST header: 'apek88.store'. You may need to add 'apek88.store' to ALLOWED_HOSTS.
ERROR 2025-07-21 18:42:10,897 log 15513 140446290404928 Invalid HTTP_HOST header: 'apek88.store'. You may need to add 'apek88.store' to ALLOWED_HOSTS.
Traceback (most recent call last):
  File "/opt/mcads/app/venv/lib/python3.10/site-packages/asgiref/sync.py", line 489, in thread_handler
    raise exc_info[1]
  File "/opt/mcads/app/venv/lib/python3.10/site-packages/django/core/handlers/exception.py", line 42, in inner
    response = await get_response(request)
  File "/opt/mcads/app/venv/lib/python3.10/site-packages/django/utils/deprecation.py", line 132, in __acall__
    response = await sync_to_async(
  File "/opt/mcads/app/venv/lib/python3.10/site-packages/asgiref/sync.py", line 439, in __call__
    ret = await asyncio.shield(exec_coro)
  File "/usr/lib/python3.10/concurrent/futures/thread.py", line 58, in run
    result = self.fn(*self.args, **self.kwargs)
  File "/opt/mcads/app/venv/lib/python3.10/site-packages/asgiref/sync.py", line 493, in thread_handler
    return func(*args, **kwargs)
  File "/opt/mcads/app/venv/lib/python3.10/site-packages/django/middleware/common.py", line 48, in process_request
    host = request.get_host()
  File "/opt/mcads/app/venv/lib/python3.10/site-packages/django/http/request.py", line 202, in get_host
    raise DisallowedHost(msg)
django.core.exceptions.DisallowedHost: Invalid HTTP_HOST header: 'apek88.store'. You may need to add 'apek88.store' to ALLOWED_HOSTS.
ERROR 2025-07-21 18:42:11,311 log 15513 140446282012224 Invalid HTTP_HOST header: 'apek88.store'. You may need to add 'apek88.store' to ALLOWED_HOSTS.
Traceback (most recent call last):
  File "/opt/mcads/app/venv/lib/python3.10/site-packages/asgiref/sync.py", line 489, in thread_handler
    raise exc_info[1]
  File "/opt/mcads/app/venv/lib/python3.10/site-packages/django/core/handlers/exception.py", line 42, in inner
    response = await get_response(request)
  File "/opt/mcads/app/venv/lib/python3.10/site-packages/django/utils/deprecation.py", line 132, in __acall__
    response = await sync_to_async(
  File "/opt/mcads/app/venv/lib/python3.10/site-packages/asgiref/sync.py", line 439, in __call__
    ret = await asyncio.shield(exec_coro)
  File "/usr/lib/python3.10/concurrent/futures/thread.py", line 58, in run
    result = self.fn(*self.args, **self.kwargs)
  File "/opt/mcads/app/venv/lib/python3.10/site-packages/asgiref/sync.py", line 493, in thread_handler
    return func(*args, **kwargs)
  File "/opt/mcads/app/venv/lib/python3.10/site-packages/django/middleware/common.py", line 48, in process_request
    host = request.get_host()
  File "/opt/mcads/app/venv/lib/python3.10/site-packages/django/http/request.py", line 202, in get_host
    raise DisallowedHost(msg)
django.core.exceptions.DisallowedHost: Invalid HTTP_HOST header: 'apek88.store'. You may need to add 'apek88.store' to ALLOWED_HOSTS.
ERROR 2025-07-21 18:42:11,516 log 15513 140446256834112 Invalid HTTP_HOST header: 'apek88.store'. You may need to add 'apek88.store' to ALLOWED_HOSTS.
Traceback (most recent call last):
  File "/opt/mcads/app/venv/lib/python3.10/site-packages/asgiref/sync.py", line 489, in thread_handler
    raise exc_info[1]
  File "/opt/mcads/app/venv/lib/python3.10/site-packages/django/core/handlers/exception.py", line 42, in inner
    response = await get_response(request)
  File "/opt/mcads/app/venv/lib/python3.10/site-packages/django/utils/deprecation.py", line 132, in __acall__
    response = await sync_to_async(
  File "/opt/mcads/app/venv/lib/python3.10/site-packages/asgiref/sync.py", line 439, in __call__
    ret = await asyncio.shield(exec_coro)
  File "/usr/lib/python3.10/concurrent/futures/thread.py", line 58, in run
    result = self.fn(*self.args, **self.kwargs)
  File "/opt/mcads/app/venv/lib/python3.10/site-packages/asgiref/sync.py", line 493, in thread_handler
    return func(*args, **kwargs)
  File "/opt/mcads/app/venv/lib/python3.10/site-packages/django/middleware/common.py", line 48, in process_request
    host = request.get_host()
  File "/opt/mcads/app/venv/lib/python3.10/site-packages/django/http/request.py", line 202, in get_host
    raise DisallowedHost(msg)
django.core.exceptions.DisallowedHost: Invalid HTTP_HOST header: 'apek88.store'. You may need to add 'apek88.store' to ALLOWED_HOSTS.
ERROR 2025-07-21 18:42:12,132 log 15513 140445749335616 Invalid HTTP_HOST header: 'apek88.store'. You may need to add 'apek88.store' to ALLOWED_HOSTS.
Traceback (most recent call last):
  File "/opt/mcads/app/venv/lib/python3.10/site-packages/asgiref/sync.py", line 489, in thread_handler
    raise exc_info[1]
  File "/opt/mcads/app/venv/lib/python3.10/site-packages/django/core/handlers/exception.py", line 42, in inner
    response = await get_response(request)
  File "/opt/mcads/app/venv/lib/python3.10/site-packages/django/utils/deprecation.py", line 132, in __acall__
    response = await sync_to_async(
  File "/opt/mcads/app/venv/lib/python3.10/site-packages/asgiref/sync.py", line 439, in __call__
    ret = await asyncio.shield(exec_coro)
  File "/usr/lib/python3.10/concurrent/futures/thread.py", line 58, in run
    result = self.fn(*self.args, **self.kwargs)
  File "/opt/mcads/app/venv/lib/python3.10/site-packages/asgiref/sync.py", line 493, in thread_handler
    return func(*args, **kwargs)
  File "/opt/mcads/app/venv/lib/python3.10/site-packages/django/middleware/common.py", line 48, in process_request
    host = request.get_host()
  File "/opt/mcads/app/venv/lib/python3.10/site-packages/django/http/request.py", line 202, in get_host
    raise DisallowedHost(msg)
django.core.exceptions.DisallowedHost: Invalid HTTP_HOST header: 'apek88.store'. You may need to add 'apek88.store' to ALLOWED_HOSTS.
ERROR 2025-07-21 18:42:12,532 log 15513 140446290404928 Invalid HTTP_HOST header: 'apek88.store'. You may need to add 'apek88.store' to ALLOWED_HOSTS.
Traceback (most recent call last):
  File "/opt/mcads/app/venv/lib/python3.10/site-packages/asgiref/sync.py", line 489, in thread_handler
    raise exc_info[1]
  File "/opt/mcads/app/venv/lib/python3.10/site-packages/django/core/handlers/exception.py", line 42, in inner
    response = await get_response(request)
  File "/opt/mcads/app/venv/lib/python3.10/site-packages/django/utils/deprecation.py", line 132, in __acall__
    response = await sync_to_async(
  File "/opt/mcads/app/venv/lib/python3.10/site-packages/asgiref/sync.py", line 439, in __call__
    ret = await asyncio.shield(exec_coro)
  File "/usr/lib/python3.10/concurrent/futures/thread.py", line 58, in run
    result = self.fn(*self.args, **self.kwargs)
  File "/opt/mcads/app/venv/lib/python3.10/site-packages/asgiref/sync.py", line 493, in thread_handler
    return func(*args, **kwargs)
  File "/opt/mcads/app/venv/lib/python3.10/site-packages/django/middleware/common.py", line 48, in process_request
    host = request.get_host()
  File "/opt/mcads/app/venv/lib/python3.10/site-packages/django/http/request.py", line 202, in get_host
    raise DisallowedHost(msg)
django.core.exceptions.DisallowedHost: Invalid HTTP_HOST header: 'apek88.store'. You may need to add 'apek88.store' to ALLOWED_HOSTS.
ERROR 2025-07-21 18:42:12,731 log 15513 140446256834112 Invalid HTTP_HOST header: 'apek88.store'. You may need to add 'apek88.store' to ALLOWED_HOSTS.
Traceback (most recent call last):
  File "/opt/mcads/app/venv/lib/python3.10/site-packages/asgiref/sync.py", line 489, in thread_handler
    raise exc_info[1]
  File "/opt/mcads/app/venv/lib/python3.10/site-packages/django/core/handlers/exception.py", line 42, in inner
    response = await get_response(request)
  File "/opt/mcads/app/venv/lib/python3.10/site-packages/django/utils/deprecation.py", line 132, in __acall__
    response = await sync_to_async(
  File "/opt/mcads/app/venv/lib/python3.10/site-packages/asgiref/sync.py", line 439, in __call__
    ret = await asyncio.shield(exec_coro)
  File "/usr/lib/python3.10/concurrent/futures/thread.py", line 58, in run
    result = self.fn(*self.args, **self.kwargs)
  File "/opt/mcads/app/venv/lib/python3.10/site-packages/asgiref/sync.py", line 493, in thread_handler
    return func(*args, **kwargs)
  File "/opt/mcads/app/venv/lib/python3.10/site-packages/django/middleware/common.py", line 48, in process_request
    host = request.get_host()
  File "/opt/mcads/app/venv/lib/python3.10/site-packages/django/http/request.py", line 202, in get_host
    raise DisallowedHost(msg)
django.core.exceptions.DisallowedHost: Invalid HTTP_HOST header: 'apek88.store'. You may need to add 'apek88.store' to ALLOWED_HOSTS.
ERROR 2025-07-21 18:42:13,133 log 15513 140446282012224 Invalid HTTP_HOST header: 'apek88.store'. You may need to add 'apek88.store' to ALLOWED_HOSTS.
Traceback (most recent call last):
  File "/opt/mcads/app/venv/lib/python3.10/site-packages/asgiref/sync.py", line 489, in thread_handler
    raise exc_info[1]
  File "/opt/mcads/app/venv/lib/python3.10/site-packages/django/core/handlers/exception.py", line 42, in inner
    response = await get_response(request)
  File "/opt/mcads/app/venv/lib/python3.10/site-packages/django/utils/deprecation.py", line 132, in __acall__
    response = await sync_to_async(
  File "/opt/mcads/app/venv/lib/python3.10/site-packages/asgiref/sync.py", line 439, in __call__
    ret = await asyncio.shield(exec_coro)
  File "/usr/lib/python3.10/concurrent/futures/thread.py", line 58, in run
    result = self.fn(*self.args, **self.kwargs)
  File "/opt/mcads/app/venv/lib/python3.10/site-packages/asgiref/sync.py", line 493, in thread_handler
    return func(*args, **kwargs)
  File "/opt/mcads/app/venv/lib/python3.10/site-packages/django/middleware/common.py", line 48, in process_request
    host = request.get_host()
  File "/opt/mcads/app/venv/lib/python3.10/site-packages/django/http/request.py", line 202, in get_host
    raise DisallowedHost(msg)
django.core.exceptions.DisallowedHost: Invalid HTTP_HOST header: 'apek88.store'. You may need to add 'apek88.store' to ALLOWED_HOSTS.
ERROR 2025-07-21 18:42:13,532 log 15513 140446290404928 Invalid HTTP_HOST header: 'apek88.store'. You may need to add 'apek88.store' to ALLOWED_HOSTS.
Traceback (most recent call last):
  File "/opt/mcads/app/venv/lib/python3.10/site-packages/asgiref/sync.py", line 489, in thread_handler
    raise exc_info[1]
  File "/opt/mcads/app/venv/lib/python3.10/site-packages/django/core/handlers/exception.py", line 42, in inner
    response = await get_response(request)
  File "/opt/mcads/app/venv/lib/python3.10/site-packages/django/utils/deprecation.py", line 132, in __acall__
    response = await sync_to_async(
  File "/opt/mcads/app/venv/lib/python3.10/site-packages/asgiref/sync.py", line 439, in __call__
    ret = await asyncio.shield(exec_coro)
  File "/usr/lib/python3.10/concurrent/futures/thread.py", line 58, in run
    result = self.fn(*self.args, **self.kwargs)
  File "/opt/mcads/app/venv/lib/python3.10/site-packages/asgiref/sync.py", line 493, in thread_handler
    return func(*args, **kwargs)
  File "/opt/mcads/app/venv/lib/python3.10/site-packages/django/middleware/common.py", line 48, in process_request
    host = request.get_host()
  File "/opt/mcads/app/venv/lib/python3.10/site-packages/django/http/request.py", line 202, in get_host
    raise DisallowedHost(msg)
django.core.exceptions.DisallowedHost: Invalid HTTP_HOST header: 'apek88.store'. You may need to add 'apek88.store' to ALLOWED_HOSTS.
ERROR 2025-07-21 18:42:14,129 log 15513 140445749335616 Invalid HTTP_HOST header: 'apek88.store'. You may need to add 'apek88.store' to ALLOWED_HOSTS.
Traceback (most recent call last):
  File "/opt/mcads/app/venv/lib/python3.10/site-packages/asgiref/sync.py", line 489, in thread_handler
    raise exc_info[1]
  File "/opt/mcads/app/venv/lib/python3.10/site-packages/django/core/handlers/exception.py", line 42, in inner
    response = await get_response(request)
  File "/opt/mcads/app/venv/lib/python3.10/site-packages/django/utils/deprecation.py", line 132, in __acall__
    response = await sync_to_async(
  File "/opt/mcads/app/venv/lib/python3.10/site-packages/asgiref/sync.py", line 439, in __call__
    ret = await asyncio.shield(exec_coro)
  File "/usr/lib/python3.10/concurrent/futures/thread.py", line 58, in run
    result = self.fn(*self.args, **self.kwargs)
  File "/opt/mcads/app/venv/lib/python3.10/site-packages/asgiref/sync.py", line 493, in thread_handler
    return func(*args, **kwargs)
  File "/opt/mcads/app/venv/lib/python3.10/site-packages/django/middleware/common.py", line 48, in process_request
    host = request.get_host()
  File "/opt/mcads/app/venv/lib/python3.10/site-packages/django/http/request.py", line 202, in get_host
    raise DisallowedHost(msg)
django.core.exceptions.DisallowedHost: Invalid HTTP_HOST header: 'apek88.store'. You may need to add 'apek88.store' to ALLOWED_HOSTS.
ERROR 2025-07-21 18:42:14,528 log 15513 140446282012224 Invalid HTTP_HOST header: 'apek88.store'. You may need to add 'apek88.store' to ALLOWED_HOSTS.
Traceback (most recent call last):
  File "/opt/mcads/app/venv/lib/python3.10/site-packages/asgiref/sync.py", line 489, in thread_handler
    raise exc_info[1]
  File "/opt/mcads/app/venv/lib/python3.10/site-packages/django/core/handlers/exception.py", line 42, in inner
    response = await get_response(request)
  File "/opt/mcads/app/venv/lib/python3.10/site-packages/django/utils/deprecation.py", line 132, in __acall__
    response = await sync_to_async(
  File "/opt/mcads/app/venv/lib/python3.10/site-packages/asgiref/sync.py", line 439, in __call__
    ret = await asyncio.shield(exec_coro)
  File "/usr/lib/python3.10/concurrent/futures/thread.py", line 58, in run
    result = self.fn(*self.args, **self.kwargs)
  File "/opt/mcads/app/venv/lib/python3.10/site-packages/asgiref/sync.py", line 493, in thread_handler
    return func(*args, **kwargs)
  File "/opt/mcads/app/venv/lib/python3.10/site-packages/django/middleware/common.py", line 48, in process_request
    host = request.get_host()
  File "/opt/mcads/app/venv/lib/python3.10/site-packages/django/http/request.py", line 202, in get_host
    raise DisallowedHost(msg)
django.core.exceptions.DisallowedHost: Invalid HTTP_HOST header: 'apek88.store'. You may need to add 'apek88.store' to ALLOWED_HOSTS.
ERROR 2025-07-21 18:42:14,725 log 15513 140446256834112 Invalid HTTP_HOST header: 'apek88.store'. You may need to add 'apek88.store' to ALLOWED_HOSTS.
Traceback (most recent call last):
  File "/opt/mcads/app/venv/lib/python3.10/site-packages/asgiref/sync.py", line 489, in thread_handler
    raise exc_info[1]
  File "/opt/mcads/app/venv/lib/python3.10/site-packages/django/core/handlers/exception.py", line 42, in inner
    response = await get_response(request)
  File "/opt/mcads/app/venv/lib/python3.10/site-packages/django/utils/deprecation.py", line 132, in __acall__
    response = await sync_to_async(
  File "/opt/mcads/app/venv/lib/python3.10/site-packages/asgiref/sync.py", line 439, in __call__
    ret = await asyncio.shield(exec_coro)
  File "/usr/lib/python3.10/concurrent/futures/thread.py", line 58, in run
    result = self.fn(*self.args, **self.kwargs)
  File "/opt/mcads/app/venv/lib/python3.10/site-packages/asgiref/sync.py", line 493, in thread_handler
    return func(*args, **kwargs)
  File "/opt/mcads/app/venv/lib/python3.10/site-packages/django/middleware/common.py", line 48, in process_request
    host = request.get_host()
  File "/opt/mcads/app/venv/lib/python3.10/site-packages/django/http/request.py", line 202, in get_host
    raise DisallowedHost(msg)
django.core.exceptions.DisallowedHost: Invalid HTTP_HOST header: 'apek88.store'. You may need to add 'apek88.store' to ALLOWED_HOSTS.
ERROR 2025-07-21 18:42:15,332 log 15513 140446290404928 Invalid HTTP_HOST header: 'apek88.store'. You may need to add 'apek88.store' to ALLOWED_HOSTS.
Traceback (most recent call last):
  File "/opt/mcads/app/venv/lib/python3.10/site-packages/asgiref/sync.py", line 489, in thread_handler
    raise exc_info[1]
  File "/opt/mcads/app/venv/lib/python3.10/site-packages/django/core/handlers/exception.py", line 42, in inner
    response = await get_response(request)
  File "/opt/mcads/app/venv/lib/python3.10/site-packages/django/utils/deprecation.py", line 132, in __acall__
    response = await sync_to_async(
  File "/opt/mcads/app/venv/lib/python3.10/site-packages/asgiref/sync.py", line 439, in __call__
    ret = await asyncio.shield(exec_coro)
  File "/usr/lib/python3.10/concurrent/futures/thread.py", line 58, in run
    result = self.fn(*self.args, **self.kwargs)
  File "/opt/mcads/app/venv/lib/python3.10/site-packages/asgiref/sync.py", line 493, in thread_handler
    return func(*args, **kwargs)
  File "/opt/mcads/app/venv/lib/python3.10/site-packages/django/middleware/common.py", line 48, in process_request
    host = request.get_host()
  File "/opt/mcads/app/venv/lib/python3.10/site-packages/django/http/request.py", line 202, in get_host
    raise DisallowedHost(msg)
django.core.exceptions.DisallowedHost: Invalid HTTP_HOST header: 'apek88.store'. You may need to add 'apek88.store' to ALLOWED_HOSTS.
ERROR 2025-07-21 18:42:15,533 log 15513 140445749335616 Invalid HTTP_HOST header: 'apek88.store'. You may need to add 'apek88.store' to ALLOWED_HOSTS.
Traceback (most recent call last):
  File "/opt/mcads/app/venv/lib/python3.10/site-packages/asgiref/sync.py", line 489, in thread_handler
    raise exc_info[1]
  File "/opt/mcads/app/venv/lib/python3.10/site-packages/django/core/handlers/exception.py", line 42, in inner
    response = await get_response(request)
  File "/opt/mcads/app/venv/lib/python3.10/site-packages/django/utils/deprecation.py", line 132, in __acall__
    response = await sync_to_async(
  File "/opt/mcads/app/venv/lib/python3.10/site-packages/asgiref/sync.py", line 439, in __call__
    ret = await asyncio.shield(exec_coro)
  File "/usr/lib/python3.10/concurrent/futures/thread.py", line 58, in run
    result = self.fn(*self.args, **self.kwargs)
  File "/opt/mcads/app/venv/lib/python3.10/site-packages/asgiref/sync.py", line 493, in thread_handler
    return func(*args, **kwargs)
  File "/opt/mcads/app/venv/lib/python3.10/site-packages/django/middleware/common.py", line 48, in process_request
    host = request.get_host()
  File "/opt/mcads/app/venv/lib/python3.10/site-packages/django/http/request.py", line 202, in get_host
    raise DisallowedHost(msg)
django.core.exceptions.DisallowedHost: Invalid HTTP_HOST header: 'apek88.store'. You may need to add 'apek88.store' to ALLOWED_HOSTS.
ERROR 2025-07-21 18:42:15,731 log 15513 140446256834112 Invalid HTTP_HOST header: 'apek88.store'. You may need to add 'apek88.store' to ALLOWED_HOSTS.
Traceback (most recent call last):
  File "/opt/mcads/app/venv/lib/python3.10/site-packages/asgiref/sync.py", line 489, in thread_handler
    raise exc_info[1]
  File "/opt/mcads/app/venv/lib/python3.10/site-packages/django/core/handlers/exception.py", line 42, in inner
    response = await get_response(request)
  File "/opt/mcads/app/venv/lib/python3.10/site-packages/django/utils/deprecation.py", line 132, in __acall__
    response = await sync_to_async(
  File "/opt/mcads/app/venv/lib/python3.10/site-packages/asgiref/sync.py", line 439, in __call__
    ret = await asyncio.shield(exec_coro)
  File "/usr/lib/python3.10/concurrent/futures/thread.py", line 58, in run
    result = self.fn(*self.args, **self.kwargs)
  File "/opt/mcads/app/venv/lib/python3.10/site-packages/asgiref/sync.py", line 493, in thread_handler
    return func(*args, **kwargs)
  File "/opt/mcads/app/venv/lib/python3.10/site-packages/django/middleware/common.py", line 48, in process_request
    host = request.get_host()
  File "/opt/mcads/app/venv/lib/python3.10/site-packages/django/http/request.py", line 202, in get_host
    raise DisallowedHost(msg)
django.core.exceptions.DisallowedHost: Invalid HTTP_HOST header: 'apek88.store'. You may need to add 'apek88.store' to ALLOWED_HOSTS.
ERROR 2025-07-21 18:42:16,141 log 15513 140446282012224 Invalid HTTP_HOST header: 'apek88.store'. You may need to add 'apek88.store' to ALLOWED_HOSTS.
Traceback (most recent call last):
  File "/opt/mcads/app/venv/lib/python3.10/site-packages/asgiref/sync.py", line 489, in thread_handler
    raise exc_info[1]
  File "/opt/mcads/app/venv/lib/python3.10/site-packages/django/core/handlers/exception.py", line 42, in inner
    response = await get_response(request)
  File "/opt/mcads/app/venv/lib/python3.10/site-packages/django/utils/deprecation.py", line 132, in __acall__
    response = await sync_to_async(
  File "/opt/mcads/app/venv/lib/python3.10/site-packages/asgiref/sync.py", line 439, in __call__
    ret = await asyncio.shield(exec_coro)
  File "/usr/lib/python3.10/concurrent/futures/thread.py", line 58, in run
    result = self.fn(*self.args, **self.kwargs)
  File "/opt/mcads/app/venv/lib/python3.10/site-packages/asgiref/sync.py", line 493, in thread_handler
    return func(*args, **kwargs)
  File "/opt/mcads/app/venv/lib/python3.10/site-packages/django/middleware/common.py", line 48, in process_request
    host = request.get_host()
  File "/opt/mcads/app/venv/lib/python3.10/site-packages/django/http/request.py", line 202, in get_host
    raise DisallowedHost(msg)
django.core.exceptions.DisallowedHost: Invalid HTTP_HOST header: 'apek88.store'. You may need to add 'apek88.store' to ALLOWED_HOSTS.
ERROR 2025-07-21 18:45:13,771 log 15513 140445749335616 Invalid HTTP_HOST header: 'topan4dd.online'. You may need to add 'topan4dd.online' to ALLOWED_HOSTS.
Traceback (most recent call last):
  File "/opt/mcads/app/venv/lib/python3.10/site-packages/asgiref/sync.py", line 489, in thread_handler
    raise exc_info[1]
  File "/opt/mcads/app/venv/lib/python3.10/site-packages/django/core/handlers/exception.py", line 42, in inner
    response = await get_response(request)
  File "/opt/mcads/app/venv/lib/python3.10/site-packages/django/utils/deprecation.py", line 132, in __acall__
    response = await sync_to_async(
  File "/opt/mcads/app/venv/lib/python3.10/site-packages/asgiref/sync.py", line 439, in __call__
    ret = await asyncio.shield(exec_coro)
  File "/usr/lib/python3.10/concurrent/futures/thread.py", line 58, in run
    result = self.fn(*self.args, **self.kwargs)
  File "/opt/mcads/app/venv/lib/python3.10/site-packages/asgiref/sync.py", line 493, in thread_handler
    return func(*args, **kwargs)
  File "/opt/mcads/app/venv/lib/python3.10/site-packages/django/middleware/common.py", line 48, in process_request
    host = request.get_host()
  File "/opt/mcads/app/venv/lib/python3.10/site-packages/django/http/request.py", line 202, in get_host
    raise DisallowedHost(msg)
django.core.exceptions.DisallowedHost: Invalid HTTP_HOST header: 'topan4dd.online'. You may need to add 'topan4dd.online' to ALLOWED_HOSTS.
ERROR 2025-07-21 18:45:14,296 log 15513 140446256834112 Invalid HTTP_HOST header: 'topan4dd.online'. You may need to add 'topan4dd.online' to ALLOWED_HOSTS.
Traceback (most recent call last):
  File "/opt/mcads/app/venv/lib/python3.10/site-packages/asgiref/sync.py", line 489, in thread_handler
    raise exc_info[1]
  File "/opt/mcads/app/venv/lib/python3.10/site-packages/django/core/handlers/exception.py", line 42, in inner
    response = await get_response(request)
  File "/opt/mcads/app/venv/lib/python3.10/site-packages/django/utils/deprecation.py", line 132, in __acall__
    response = await sync_to_async(
  File "/opt/mcads/app/venv/lib/python3.10/site-packages/asgiref/sync.py", line 439, in __call__
    ret = await asyncio.shield(exec_coro)
  File "/usr/lib/python3.10/concurrent/futures/thread.py", line 58, in run
    result = self.fn(*self.args, **self.kwargs)
  File "/opt/mcads/app/venv/lib/python3.10/site-packages/asgiref/sync.py", line 493, in thread_handler
    return func(*args, **kwargs)
  File "/opt/mcads/app/venv/lib/python3.10/site-packages/django/middleware/common.py", line 48, in process_request
    host = request.get_host()
  File "/opt/mcads/app/venv/lib/python3.10/site-packages/django/http/request.py", line 202, in get_host
    raise DisallowedHost(msg)
django.core.exceptions.DisallowedHost: Invalid HTTP_HOST header: 'topan4dd.online'. You may need to add 'topan4dd.online' to ALLOWED_HOSTS.
ERROR 2025-07-21 18:45:14,760 log 15513 140446290404928 Invalid HTTP_HOST header: 'topan4dd.online'. You may need to add 'topan4dd.online' to ALLOWED_HOSTS.
Traceback (most recent call last):
  File "/opt/mcads/app/venv/lib/python3.10/site-packages/asgiref/sync.py", line 489, in thread_handler
    raise exc_info[1]
  File "/opt/mcads/app/venv/lib/python3.10/site-packages/django/core/handlers/exception.py", line 42, in inner
    response = await get_response(request)
  File "/opt/mcads/app/venv/lib/python3.10/site-packages/django/utils/deprecation.py", line 132, in __acall__
    response = await sync_to_async(
  File "/opt/mcads/app/venv/lib/python3.10/site-packages/asgiref/sync.py", line 439, in __call__
    ret = await asyncio.shield(exec_coro)
  File "/usr/lib/python3.10/concurrent/futures/thread.py", line 58, in run
    result = self.fn(*self.args, **self.kwargs)
  File "/opt/mcads/app/venv/lib/python3.10/site-packages/asgiref/sync.py", line 493, in thread_handler
    return func(*args, **kwargs)
  File "/opt/mcads/app/venv/lib/python3.10/site-packages/django/middleware/common.py", line 48, in process_request
    host = request.get_host()
  File "/opt/mcads/app/venv/lib/python3.10/site-packages/django/http/request.py", line 202, in get_host
    raise DisallowedHost(msg)
django.core.exceptions.DisallowedHost: Invalid HTTP_HOST header: 'topan4dd.online'. You may need to add 'topan4dd.online' to ALLOWED_HOSTS.
ERROR 2025-07-21 18:45:14,966 log 15513 140446282012224 Invalid HTTP_HOST header: 'topan4dd.online'. You may need to add 'topan4dd.online' to ALLOWED_HOSTS.
Traceback (most recent call last):
  File "/opt/mcads/app/venv/lib/python3.10/site-packages/asgiref/sync.py", line 489, in thread_handler
    raise exc_info[1]
  File "/opt/mcads/app/venv/lib/python3.10/site-packages/django/core/handlers/exception.py", line 42, in inner
    response = await get_response(request)
  File "/opt/mcads/app/venv/lib/python3.10/site-packages/django/utils/deprecation.py", line 132, in __acall__
    response = await sync_to_async(
  File "/opt/mcads/app/venv/lib/python3.10/site-packages/asgiref/sync.py", line 439, in __call__
    ret = await asyncio.shield(exec_coro)
  File "/usr/lib/python3.10/concurrent/futures/thread.py", line 58, in run
    result = self.fn(*self.args, **self.kwargs)
  File "/opt/mcads/app/venv/lib/python3.10/site-packages/asgiref/sync.py", line 493, in thread_handler
    return func(*args, **kwargs)
  File "/opt/mcads/app/venv/lib/python3.10/site-packages/django/middleware/common.py", line 48, in process_request
    host = request.get_host()
  File "/opt/mcads/app/venv/lib/python3.10/site-packages/django/http/request.py", line 202, in get_host
    raise DisallowedHost(msg)
django.core.exceptions.DisallowedHost: Invalid HTTP_HOST header: 'topan4dd.online'. You may need to add 'topan4dd.online' to ALLOWED_HOSTS.
ERROR 2025-07-21 18:45:15,374 log 15513 140445749335616 Invalid HTTP_HOST header: 'topan4dd.online'. You may need to add 'topan4dd.online' to ALLOWED_HOSTS.
Traceback (most recent call last):
  File "/opt/mcads/app/venv/lib/python3.10/site-packages/asgiref/sync.py", line 489, in thread_handler
    raise exc_info[1]
  File "/opt/mcads/app/venv/lib/python3.10/site-packages/django/core/handlers/exception.py", line 42, in inner
    response = await get_response(request)
  File "/opt/mcads/app/venv/lib/python3.10/site-packages/django/utils/deprecation.py", line 132, in __acall__
    response = await sync_to_async(
  File "/opt/mcads/app/venv/lib/python3.10/site-packages/asgiref/sync.py", line 439, in __call__
    ret = await asyncio.shield(exec_coro)
  File "/usr/lib/python3.10/concurrent/futures/thread.py", line 58, in run
    result = self.fn(*self.args, **self.kwargs)
  File "/opt/mcads/app/venv/lib/python3.10/site-packages/asgiref/sync.py", line 493, in thread_handler
    return func(*args, **kwargs)
  File "/opt/mcads/app/venv/lib/python3.10/site-packages/django/middleware/common.py", line 48, in process_request
    host = request.get_host()
  File "/opt/mcads/app/venv/lib/python3.10/site-packages/django/http/request.py", line 202, in get_host
    raise DisallowedHost(msg)
django.core.exceptions.DisallowedHost: Invalid HTTP_HOST header: 'topan4dd.online'. You may need to add 'topan4dd.online' to ALLOWED_HOSTS.
ERROR 2025-07-21 18:45:15,730 log 15513 140446290404928 Invalid HTTP_HOST header: 'topan4dd.online'. You may need to add 'topan4dd.online' to ALLOWED_HOSTS.
Traceback (most recent call last):
  File "/opt/mcads/app/venv/lib/python3.10/site-packages/asgiref/sync.py", line 489, in thread_handler
    raise exc_info[1]
  File "/opt/mcads/app/venv/lib/python3.10/site-packages/django/core/handlers/exception.py", line 42, in inner
    response = await get_response(request)
  File "/opt/mcads/app/venv/lib/python3.10/site-packages/django/utils/deprecation.py", line 132, in __acall__
    response = await sync_to_async(
  File "/opt/mcads/app/venv/lib/python3.10/site-packages/asgiref/sync.py", line 439, in __call__
    ret = await asyncio.shield(exec_coro)
  File "/usr/lib/python3.10/concurrent/futures/thread.py", line 58, in run
    result = self.fn(*self.args, **self.kwargs)
  File "/opt/mcads/app/venv/lib/python3.10/site-packages/asgiref/sync.py", line 493, in thread_handler
    return func(*args, **kwargs)
  File "/opt/mcads/app/venv/lib/python3.10/site-packages/django/middleware/common.py", line 48, in process_request
    host = request.get_host()
  File "/opt/mcads/app/venv/lib/python3.10/site-packages/django/http/request.py", line 202, in get_host
    raise DisallowedHost(msg)
django.core.exceptions.DisallowedHost: Invalid HTTP_HOST header: 'topan4dd.online'. You may need to add 'topan4dd.online' to ALLOWED_HOSTS.
ERROR 2025-07-21 18:45:15,979 log 15513 140446256834112 Invalid HTTP_HOST header: 'topan4dd.online'. You may need to add 'topan4dd.online' to ALLOWED_HOSTS.
Traceback (most recent call last):
  File "/opt/mcads/app/venv/lib/python3.10/site-packages/asgiref/sync.py", line 489, in thread_handler
    raise exc_info[1]
  File "/opt/mcads/app/venv/lib/python3.10/site-packages/django/core/handlers/exception.py", line 42, in inner
    response = await get_response(request)
  File "/opt/mcads/app/venv/lib/python3.10/site-packages/django/utils/deprecation.py", line 132, in __acall__
    response = await sync_to_async(
  File "/opt/mcads/app/venv/lib/python3.10/site-packages/asgiref/sync.py", line 439, in __call__
    ret = await asyncio.shield(exec_coro)
  File "/usr/lib/python3.10/concurrent/futures/thread.py", line 58, in run
    result = self.fn(*self.args, **self.kwargs)
  File "/opt/mcads/app/venv/lib/python3.10/site-packages/asgiref/sync.py", line 493, in thread_handler
    return func(*args, **kwargs)
  File "/opt/mcads/app/venv/lib/python3.10/site-packages/django/middleware/common.py", line 48, in process_request
    host = request.get_host()
  File "/opt/mcads/app/venv/lib/python3.10/site-packages/django/http/request.py", line 202, in get_host
    raise DisallowedHost(msg)
django.core.exceptions.DisallowedHost: Invalid HTTP_HOST header: 'topan4dd.online'. You may need to add 'topan4dd.online' to ALLOWED_HOSTS.
ERROR 2025-07-21 18:45:16,177 log 15513 140445749335616 Invalid HTTP_HOST header: 'topan4dd.online'. You may need to add 'topan4dd.online' to ALLOWED_HOSTS.
Traceback (most recent call last):
  File "/opt/mcads/app/venv/lib/python3.10/site-packages/asgiref/sync.py", line 489, in thread_handler
    raise exc_info[1]
  File "/opt/mcads/app/venv/lib/python3.10/site-packages/django/core/handlers/exception.py", line 42, in inner
    response = await get_response(request)
  File "/opt/mcads/app/venv/lib/python3.10/site-packages/django/utils/deprecation.py", line 132, in __acall__
    response = await sync_to_async(
  File "/opt/mcads/app/venv/lib/python3.10/site-packages/asgiref/sync.py", line 439, in __call__
    ret = await asyncio.shield(exec_coro)
  File "/usr/lib/python3.10/concurrent/futures/thread.py", line 58, in run
    result = self.fn(*self.args, **self.kwargs)
  File "/opt/mcads/app/venv/lib/python3.10/site-packages/asgiref/sync.py", line 493, in thread_handler
    return func(*args, **kwargs)
  File "/opt/mcads/app/venv/lib/python3.10/site-packages/django/middleware/common.py", line 48, in process_request
    host = request.get_host()
  File "/opt/mcads/app/venv/lib/python3.10/site-packages/django/http/request.py", line 202, in get_host
    raise DisallowedHost(msg)
django.core.exceptions.DisallowedHost: Invalid HTTP_HOST header: 'topan4dd.online'. You may need to add 'topan4dd.online' to ALLOWED_HOSTS.
ERROR 2025-07-21 18:45:16,904 log 15513 140446282012224 Invalid HTTP_HOST header: 'topan4dd.online'. You may need to add 'topan4dd.online' to ALLOWED_HOSTS.
Traceback (most recent call last):
  File "/opt/mcads/app/venv/lib/python3.10/site-packages/asgiref/sync.py", line 489, in thread_handler
    raise exc_info[1]
  File "/opt/mcads/app/venv/lib/python3.10/site-packages/django/core/handlers/exception.py", line 42, in inner
    response = await get_response(request)
  File "/opt/mcads/app/venv/lib/python3.10/site-packages/django/utils/deprecation.py", line 132, in __acall__
    response = await sync_to_async(
  File "/opt/mcads/app/venv/lib/python3.10/site-packages/asgiref/sync.py", line 439, in __call__
    ret = await asyncio.shield(exec_coro)
  File "/usr/lib/python3.10/concurrent/futures/thread.py", line 58, in run
    result = self.fn(*self.args, **self.kwargs)
  File "/opt/mcads/app/venv/lib/python3.10/site-packages/asgiref/sync.py", line 493, in thread_handler
    return func(*args, **kwargs)
  File "/opt/mcads/app/venv/lib/python3.10/site-packages/django/middleware/common.py", line 48, in process_request
    host = request.get_host()
  File "/opt/mcads/app/venv/lib/python3.10/site-packages/django/http/request.py", line 202, in get_host
    raise DisallowedHost(msg)
django.core.exceptions.DisallowedHost: Invalid HTTP_HOST header: 'topan4dd.online'. You may need to add 'topan4dd.online' to ALLOWED_HOSTS.
ERROR 2025-07-21 18:45:17,302 log 15513 140446290404928 Invalid HTTP_HOST header: 'topan4dd.online'. You may need to add 'topan4dd.online' to ALLOWED_HOSTS.
Traceback (most recent call last):
  File "/opt/mcads/app/venv/lib/python3.10/site-packages/asgiref/sync.py", line 489, in thread_handler
    raise exc_info[1]
  File "/opt/mcads/app/venv/lib/python3.10/site-packages/django/core/handlers/exception.py", line 42, in inner
    response = await get_response(request)
  File "/opt/mcads/app/venv/lib/python3.10/site-packages/django/utils/deprecation.py", line 132, in __acall__
    response = await sync_to_async(
  File "/opt/mcads/app/venv/lib/python3.10/site-packages/asgiref/sync.py", line 439, in __call__
    ret = await asyncio.shield(exec_coro)
  File "/usr/lib/python3.10/concurrent/futures/thread.py", line 58, in run
    result = self.fn(*self.args, **self.kwargs)
  File "/opt/mcads/app/venv/lib/python3.10/site-packages/asgiref/sync.py", line 493, in thread_handler
    return func(*args, **kwargs)
  File "/opt/mcads/app/venv/lib/python3.10/site-packages/django/middleware/common.py", line 48, in process_request
    host = request.get_host()
  File "/opt/mcads/app/venv/lib/python3.10/site-packages/django/http/request.py", line 202, in get_host
    raise DisallowedHost(msg)
django.core.exceptions.DisallowedHost: Invalid HTTP_HOST header: 'topan4dd.online'. You may need to add 'topan4dd.online' to ALLOWED_HOSTS.
ERROR 2025-07-21 18:45:17,713 log 15513 140446256834112 Invalid HTTP_HOST header: 'topan4dd.online'. You may need to add 'topan4dd.online' to ALLOWED_HOSTS.
Traceback (most recent call last):
  File "/opt/mcads/app/venv/lib/python3.10/site-packages/asgiref/sync.py", line 489, in thread_handler
    raise exc_info[1]
  File "/opt/mcads/app/venv/lib/python3.10/site-packages/django/core/handlers/exception.py", line 42, in inner
    response = await get_response(request)
  File "/opt/mcads/app/venv/lib/python3.10/site-packages/django/utils/deprecation.py", line 132, in __acall__
    response = await sync_to_async(
  File "/opt/mcads/app/venv/lib/python3.10/site-packages/asgiref/sync.py", line 439, in __call__
    ret = await asyncio.shield(exec_coro)
  File "/usr/lib/python3.10/concurrent/futures/thread.py", line 58, in run
    result = self.fn(*self.args, **self.kwargs)
  File "/opt/mcads/app/venv/lib/python3.10/site-packages/asgiref/sync.py", line 493, in thread_handler
    return func(*args, **kwargs)
  File "/opt/mcads/app/venv/lib/python3.10/site-packages/django/middleware/common.py", line 48, in process_request
    host = request.get_host()
  File "/opt/mcads/app/venv/lib/python3.10/site-packages/django/http/request.py", line 202, in get_host
    raise DisallowedHost(msg)
django.core.exceptions.DisallowedHost: Invalid HTTP_HOST header: 'topan4dd.online'. You may need to add 'topan4dd.online' to ALLOWED_HOSTS.
ERROR 2025-07-21 18:45:18,140 log 15513 140445749335616 Invalid HTTP_HOST header: 'topan4dd.online'. You may need to add 'topan4dd.online' to ALLOWED_HOSTS.
Traceback (most recent call last):
  File "/opt/mcads/app/venv/lib/python3.10/site-packages/asgiref/sync.py", line 489, in thread_handler
    raise exc_info[1]
  File "/opt/mcads/app/venv/lib/python3.10/site-packages/django/core/handlers/exception.py", line 42, in inner
    response = await get_response(request)
  File "/opt/mcads/app/venv/lib/python3.10/site-packages/django/utils/deprecation.py", line 132, in __acall__
    response = await sync_to_async(
  File "/opt/mcads/app/venv/lib/python3.10/site-packages/asgiref/sync.py", line 439, in __call__
    ret = await asyncio.shield(exec_coro)
  File "/usr/lib/python3.10/concurrent/futures/thread.py", line 58, in run
    result = self.fn(*self.args, **self.kwargs)
  File "/opt/mcads/app/venv/lib/python3.10/site-packages/asgiref/sync.py", line 493, in thread_handler
    return func(*args, **kwargs)
  File "/opt/mcads/app/venv/lib/python3.10/site-packages/django/middleware/common.py", line 48, in process_request
    host = request.get_host()
  File "/opt/mcads/app/venv/lib/python3.10/site-packages/django/http/request.py", line 202, in get_host
    raise DisallowedHost(msg)
django.core.exceptions.DisallowedHost: Invalid HTTP_HOST header: 'topan4dd.online'. You may need to add 'topan4dd.online' to ALLOWED_HOSTS.
ERROR 2025-07-21 18:45:18,342 log 15513 140446290404928 Invalid HTTP_HOST header: 'topan4dd.online'. You may need to add 'topan4dd.online' to ALLOWED_HOSTS.
Traceback (most recent call last):
  File "/opt/mcads/app/venv/lib/python3.10/site-packages/asgiref/sync.py", line 489, in thread_handler
    raise exc_info[1]
  File "/opt/mcads/app/venv/lib/python3.10/site-packages/django/core/handlers/exception.py", line 42, in inner
    response = await get_response(request)
  File "/opt/mcads/app/venv/lib/python3.10/site-packages/django/utils/deprecation.py", line 132, in __acall__
    response = await sync_to_async(
  File "/opt/mcads/app/venv/lib/python3.10/site-packages/asgiref/sync.py", line 439, in __call__
    ret = await asyncio.shield(exec_coro)
  File "/usr/lib/python3.10/concurrent/futures/thread.py", line 58, in run
    result = self.fn(*self.args, **self.kwargs)
  File "/opt/mcads/app/venv/lib/python3.10/site-packages/asgiref/sync.py", line 493, in thread_handler
    return func(*args, **kwargs)
  File "/opt/mcads/app/venv/lib/python3.10/site-packages/django/middleware/common.py", line 48, in process_request
    host = request.get_host()
  File "/opt/mcads/app/venv/lib/python3.10/site-packages/django/http/request.py", line 202, in get_host
    raise DisallowedHost(msg)
django.core.exceptions.DisallowedHost: Invalid HTTP_HOST header: 'topan4dd.online'. You may need to add 'topan4dd.online' to ALLOWED_HOSTS.
ERROR 2025-07-21 18:45:18,540 log 15513 140446256834112 Invalid HTTP_HOST header: 'topan4dd.online'. You may need to add 'topan4dd.online' to ALLOWED_HOSTS.
Traceback (most recent call last):
  File "/opt/mcads/app/venv/lib/python3.10/site-packages/asgiref/sync.py", line 489, in thread_handler
    raise exc_info[1]
  File "/opt/mcads/app/venv/lib/python3.10/site-packages/django/core/handlers/exception.py", line 42, in inner
    response = await get_response(request)
  File "/opt/mcads/app/venv/lib/python3.10/site-packages/django/utils/deprecation.py", line 132, in __acall__
    response = await sync_to_async(
  File "/opt/mcads/app/venv/lib/python3.10/site-packages/asgiref/sync.py", line 439, in __call__
    ret = await asyncio.shield(exec_coro)
  File "/usr/lib/python3.10/concurrent/futures/thread.py", line 58, in run
    result = self.fn(*self.args, **self.kwargs)
  File "/opt/mcads/app/venv/lib/python3.10/site-packages/asgiref/sync.py", line 493, in thread_handler
    return func(*args, **kwargs)
  File "/opt/mcads/app/venv/lib/python3.10/site-packages/django/middleware/common.py", line 48, in process_request
    host = request.get_host()
  File "/opt/mcads/app/venv/lib/python3.10/site-packages/django/http/request.py", line 202, in get_host
    raise DisallowedHost(msg)
django.core.exceptions.DisallowedHost: Invalid HTTP_HOST header: 'topan4dd.online'. You may need to add 'topan4dd.online' to ALLOWED_HOSTS.
ERROR 2025-07-21 18:45:18,747 log 15513 140446282012224 Invalid HTTP_HOST header: 'topan4dd.online'. You may need to add 'topan4dd.online' to ALLOWED_HOSTS.
Traceback (most recent call last):
  File "/opt/mcads/app/venv/lib/python3.10/site-packages/asgiref/sync.py", line 489, in thread_handler
    raise exc_info[1]
  File "/opt/mcads/app/venv/lib/python3.10/site-packages/django/core/handlers/exception.py", line 42, in inner
    response = await get_response(request)
  File "/opt/mcads/app/venv/lib/python3.10/site-packages/django/utils/deprecation.py", line 132, in __acall__
    response = await sync_to_async(
  File "/opt/mcads/app/venv/lib/python3.10/site-packages/asgiref/sync.py", line 439, in __call__
    ret = await asyncio.shield(exec_coro)
  File "/usr/lib/python3.10/concurrent/futures/thread.py", line 58, in run
    result = self.fn(*self.args, **self.kwargs)
  File "/opt/mcads/app/venv/lib/python3.10/site-packages/asgiref/sync.py", line 493, in thread_handler
    return func(*args, **kwargs)
  File "/opt/mcads/app/venv/lib/python3.10/site-packages/django/middleware/common.py", line 48, in process_request
    host = request.get_host()
  File "/opt/mcads/app/venv/lib/python3.10/site-packages/django/http/request.py", line 202, in get_host
    raise DisallowedHost(msg)
django.core.exceptions.DisallowedHost: Invalid HTTP_HOST header: 'topan4dd.online'. You may need to add 'topan4dd.online' to ALLOWED_HOSTS.
ERROR 2025-07-21 18:45:19,414 log 15513 140446290404928 Invalid HTTP_HOST header: 'topan4dd.online'. You may need to add 'topan4dd.online' to ALLOWED_HOSTS.
Traceback (most recent call last):
  File "/opt/mcads/app/venv/lib/python3.10/site-packages/asgiref/sync.py", line 489, in thread_handler
    raise exc_info[1]
  File "/opt/mcads/app/venv/lib/python3.10/site-packages/django/core/handlers/exception.py", line 42, in inner
    response = await get_response(request)
  File "/opt/mcads/app/venv/lib/python3.10/site-packages/django/utils/deprecation.py", line 132, in __acall__
    response = await sync_to_async(
  File "/opt/mcads/app/venv/lib/python3.10/site-packages/asgiref/sync.py", line 439, in __call__
    ret = await asyncio.shield(exec_coro)
  File "/usr/lib/python3.10/concurrent/futures/thread.py", line 58, in run
    result = self.fn(*self.args, **self.kwargs)
  File "/opt/mcads/app/venv/lib/python3.10/site-packages/asgiref/sync.py", line 493, in thread_handler
    return func(*args, **kwargs)
  File "/opt/mcads/app/venv/lib/python3.10/site-packages/django/middleware/common.py", line 48, in process_request
    host = request.get_host()
  File "/opt/mcads/app/venv/lib/python3.10/site-packages/django/http/request.py", line 202, in get_host
    raise DisallowedHost(msg)
django.core.exceptions.DisallowedHost: Invalid HTTP_HOST header: 'topan4dd.online'. You may need to add 'topan4dd.online' to ALLOWED_HOSTS.
ERROR 2025-07-21 18:45:19,610 log 15513 140446256834112 Invalid HTTP_HOST header: 'topan4dd.online'. You may need to add 'topan4dd.online' to ALLOWED_HOSTS.
Traceback (most recent call last):
  File "/opt/mcads/app/venv/lib/python3.10/site-packages/asgiref/sync.py", line 489, in thread_handler
    raise exc_info[1]
  File "/opt/mcads/app/venv/lib/python3.10/site-packages/django/core/handlers/exception.py", line 42, in inner
    response = await get_response(request)
  File "/opt/mcads/app/venv/lib/python3.10/site-packages/django/utils/deprecation.py", line 132, in __acall__
    response = await sync_to_async(
  File "/opt/mcads/app/venv/lib/python3.10/site-packages/asgiref/sync.py", line 439, in __call__
    ret = await asyncio.shield(exec_coro)
  File "/usr/lib/python3.10/concurrent/futures/thread.py", line 58, in run
    result = self.fn(*self.args, **self.kwargs)
  File "/opt/mcads/app/venv/lib/python3.10/site-packages/asgiref/sync.py", line 493, in thread_handler
    return func(*args, **kwargs)
  File "/opt/mcads/app/venv/lib/python3.10/site-packages/django/middleware/common.py", line 48, in process_request
    host = request.get_host()
  File "/opt/mcads/app/venv/lib/python3.10/site-packages/django/http/request.py", line 202, in get_host
    raise DisallowedHost(msg)
django.core.exceptions.DisallowedHost: Invalid HTTP_HOST header: 'topan4dd.online'. You may need to add 'topan4dd.online' to ALLOWED_HOSTS.
ERROR 2025-07-21 18:45:20,181 log 15513 140445749335616 Invalid HTTP_HOST header: 'topan4dd.online'. You may need to add 'topan4dd.online' to ALLOWED_HOSTS.
Traceback (most recent call last):
  File "/opt/mcads/app/venv/lib/python3.10/site-packages/asgiref/sync.py", line 489, in thread_handler
    raise exc_info[1]
  File "/opt/mcads/app/venv/lib/python3.10/site-packages/django/core/handlers/exception.py", line 42, in inner
    response = await get_response(request)
  File "/opt/mcads/app/venv/lib/python3.10/site-packages/django/utils/deprecation.py", line 132, in __acall__
    response = await sync_to_async(
  File "/opt/mcads/app/venv/lib/python3.10/site-packages/asgiref/sync.py", line 439, in __call__
    ret = await asyncio.shield(exec_coro)
  File "/usr/lib/python3.10/concurrent/futures/thread.py", line 58, in run
    result = self.fn(*self.args, **self.kwargs)
  File "/opt/mcads/app/venv/lib/python3.10/site-packages/asgiref/sync.py", line 493, in thread_handler
    return func(*args, **kwargs)
  File "/opt/mcads/app/venv/lib/python3.10/site-packages/django/middleware/common.py", line 48, in process_request
    host = request.get_host()
  File "/opt/mcads/app/venv/lib/python3.10/site-packages/django/http/request.py", line 202, in get_host
    raise DisallowedHost(msg)
django.core.exceptions.DisallowedHost: Invalid HTTP_HOST header: 'topan4dd.online'. You may need to add 'topan4dd.online' to ALLOWED_HOSTS.
ERROR 2025-07-21 18:45:20,443 log 15513 140446290404928 Invalid HTTP_HOST header: 'topan4dd.online'. You may need to add 'topan4dd.online' to ALLOWED_HOSTS.
Traceback (most recent call last):
  File "/opt/mcads/app/venv/lib/python3.10/site-packages/asgiref/sync.py", line 489, in thread_handler
    raise exc_info[1]
  File "/opt/mcads/app/venv/lib/python3.10/site-packages/django/core/handlers/exception.py", line 42, in inner
    response = await get_response(request)
  File "/opt/mcads/app/venv/lib/python3.10/site-packages/django/utils/deprecation.py", line 132, in __acall__
    response = await sync_to_async(
  File "/opt/mcads/app/venv/lib/python3.10/site-packages/asgiref/sync.py", line 439, in __call__
    ret = await asyncio.shield(exec_coro)
  File "/usr/lib/python3.10/concurrent/futures/thread.py", line 58, in run
    result = self.fn(*self.args, **self.kwargs)
  File "/opt/mcads/app/venv/lib/python3.10/site-packages/asgiref/sync.py", line 493, in thread_handler
    return func(*args, **kwargs)
  File "/opt/mcads/app/venv/lib/python3.10/site-packages/django/middleware/common.py", line 48, in process_request
    host = request.get_host()
  File "/opt/mcads/app/venv/lib/python3.10/site-packages/django/http/request.py", line 202, in get_host
    raise DisallowedHost(msg)
django.core.exceptions.DisallowedHost: Invalid HTTP_HOST header: 'topan4dd.online'. You may need to add 'topan4dd.online' to ALLOWED_HOSTS.
ERROR 2025-07-21 18:45:20,858 log 15513 140446282012224 Invalid HTTP_HOST header: 'topan4dd.online'. You may need to add 'topan4dd.online' to ALLOWED_HOSTS.
Traceback (most recent call last):
  File "/opt/mcads/app/venv/lib/python3.10/site-packages/asgiref/sync.py", line 489, in thread_handler
    raise exc_info[1]
  File "/opt/mcads/app/venv/lib/python3.10/site-packages/django/core/handlers/exception.py", line 42, in inner
    response = await get_response(request)
  File "/opt/mcads/app/venv/lib/python3.10/site-packages/django/utils/deprecation.py", line 132, in __acall__
    response = await sync_to_async(
  File "/opt/mcads/app/venv/lib/python3.10/site-packages/asgiref/sync.py", line 439, in __call__
    ret = await asyncio.shield(exec_coro)
  File "/usr/lib/python3.10/concurrent/futures/thread.py", line 58, in run
    result = self.fn(*self.args, **self.kwargs)
  File "/opt/mcads/app/venv/lib/python3.10/site-packages/asgiref/sync.py", line 493, in thread_handler
    return func(*args, **kwargs)
  File "/opt/mcads/app/venv/lib/python3.10/site-packages/django/middleware/common.py", line 48, in process_request
    host = request.get_host()
  File "/opt/mcads/app/venv/lib/python3.10/site-packages/django/http/request.py", line 202, in get_host
    raise DisallowedHost(msg)
django.core.exceptions.DisallowedHost: Invalid HTTP_HOST header: 'topan4dd.online'. You may need to add 'topan4dd.online' to ALLOWED_HOSTS.
ERROR 2025-07-21 18:45:21,063 log 15513 140446290404928 Invalid HTTP_HOST header: 'topan4dd.online'. You may need to add 'topan4dd.online' to ALLOWED_HOSTS.
Traceback (most recent call last):
  File "/opt/mcads/app/venv/lib/python3.10/site-packages/asgiref/sync.py", line 489, in thread_handler
    raise exc_info[1]
  File "/opt/mcads/app/venv/lib/python3.10/site-packages/django/core/handlers/exception.py", line 42, in inner
    response = await get_response(request)
  File "/opt/mcads/app/venv/lib/python3.10/site-packages/django/utils/deprecation.py", line 132, in __acall__
    response = await sync_to_async(
  File "/opt/mcads/app/venv/lib/python3.10/site-packages/asgiref/sync.py", line 439, in __call__
    ret = await asyncio.shield(exec_coro)
  File "/usr/lib/python3.10/concurrent/futures/thread.py", line 58, in run
    result = self.fn(*self.args, **self.kwargs)
  File "/opt/mcads/app/venv/lib/python3.10/site-packages/asgiref/sync.py", line 493, in thread_handler
    return func(*args, **kwargs)
  File "/opt/mcads/app/venv/lib/python3.10/site-packages/django/middleware/common.py", line 48, in process_request
    host = request.get_host()
  File "/opt/mcads/app/venv/lib/python3.10/site-packages/django/http/request.py", line 202, in get_host
    raise DisallowedHost(msg)
django.core.exceptions.DisallowedHost: Invalid HTTP_HOST header: 'topan4dd.online'. You may need to add 'topan4dd.online' to ALLOWED_HOSTS.
ERROR 2025-07-21 18:45:21,263 log 15513 140445749335616 Invalid HTTP_HOST header: 'topan4dd.online'. You may need to add 'topan4dd.online' to ALLOWED_HOSTS.
Traceback (most recent call last):
  File "/opt/mcads/app/venv/lib/python3.10/site-packages/asgiref/sync.py", line 489, in thread_handler
    raise exc_info[1]
  File "/opt/mcads/app/venv/lib/python3.10/site-packages/django/core/handlers/exception.py", line 42, in inner
    response = await get_response(request)
  File "/opt/mcads/app/venv/lib/python3.10/site-packages/django/utils/deprecation.py", line 132, in __acall__
    response = await sync_to_async(
  File "/opt/mcads/app/venv/lib/python3.10/site-packages/asgiref/sync.py", line 439, in __call__
    ret = await asyncio.shield(exec_coro)
  File "/usr/lib/python3.10/concurrent/futures/thread.py", line 58, in run
    result = self.fn(*self.args, **self.kwargs)
  File "/opt/mcads/app/venv/lib/python3.10/site-packages/asgiref/sync.py", line 493, in thread_handler
    return func(*args, **kwargs)
  File "/opt/mcads/app/venv/lib/python3.10/site-packages/django/middleware/common.py", line 48, in process_request
    host = request.get_host()
  File "/opt/mcads/app/venv/lib/python3.10/site-packages/django/http/request.py", line 202, in get_host
    raise DisallowedHost(msg)
django.core.exceptions.DisallowedHost: Invalid HTTP_HOST header: 'topan4dd.online'. You may need to add 'topan4dd.online' to ALLOWED_HOSTS.
ERROR 2025-07-21 18:45:21,913 log 15513 140446282012224 Invalid HTTP_HOST header: 'topan4dd.online'. You may need to add 'topan4dd.online' to ALLOWED_HOSTS.
Traceback (most recent call last):
  File "/opt/mcads/app/venv/lib/python3.10/site-packages/asgiref/sync.py", line 489, in thread_handler
    raise exc_info[1]
  File "/opt/mcads/app/venv/lib/python3.10/site-packages/django/core/handlers/exception.py", line 42, in inner
    response = await get_response(request)
  File "/opt/mcads/app/venv/lib/python3.10/site-packages/django/utils/deprecation.py", line 132, in __acall__
    response = await sync_to_async(
  File "/opt/mcads/app/venv/lib/python3.10/site-packages/asgiref/sync.py", line 439, in __call__
    ret = await asyncio.shield(exec_coro)
  File "/usr/lib/python3.10/concurrent/futures/thread.py", line 58, in run
    result = self.fn(*self.args, **self.kwargs)
  File "/opt/mcads/app/venv/lib/python3.10/site-packages/asgiref/sync.py", line 493, in thread_handler
    return func(*args, **kwargs)
  File "/opt/mcads/app/venv/lib/python3.10/site-packages/django/middleware/common.py", line 48, in process_request
    host = request.get_host()
  File "/opt/mcads/app/venv/lib/python3.10/site-packages/django/http/request.py", line 202, in get_host
    raise DisallowedHost(msg)
django.core.exceptions.DisallowedHost: Invalid HTTP_HOST header: 'topan4dd.online'. You may need to add 'topan4dd.online' to ALLOWED_HOSTS.
ERROR 2025-07-21 18:45:22,320 log 15513 140446256834112 Invalid HTTP_HOST header: 'topan4dd.online'. You may need to add 'topan4dd.online' to ALLOWED_HOSTS.
Traceback (most recent call last):
  File "/opt/mcads/app/venv/lib/python3.10/site-packages/asgiref/sync.py", line 489, in thread_handler
    raise exc_info[1]
  File "/opt/mcads/app/venv/lib/python3.10/site-packages/django/core/handlers/exception.py", line 42, in inner
    response = await get_response(request)
  File "/opt/mcads/app/venv/lib/python3.10/site-packages/django/utils/deprecation.py", line 132, in __acall__
    response = await sync_to_async(
  File "/opt/mcads/app/venv/lib/python3.10/site-packages/asgiref/sync.py", line 439, in __call__
    ret = await asyncio.shield(exec_coro)
  File "/usr/lib/python3.10/concurrent/futures/thread.py", line 58, in run
    result = self.fn(*self.args, **self.kwargs)
  File "/opt/mcads/app/venv/lib/python3.10/site-packages/asgiref/sync.py", line 493, in thread_handler
    return func(*args, **kwargs)
  File "/opt/mcads/app/venv/lib/python3.10/site-packages/django/middleware/common.py", line 48, in process_request
    host = request.get_host()
  File "/opt/mcads/app/venv/lib/python3.10/site-packages/django/http/request.py", line 202, in get_host
    raise DisallowedHost(msg)
django.core.exceptions.DisallowedHost: Invalid HTTP_HOST header: 'topan4dd.online'. You may need to add 'topan4dd.online' to ALLOWED_HOSTS.
ERROR 2025-07-21 18:45:22,516 log 15513 140445749335616 Invalid HTTP_HOST header: 'topan4dd.online'. You may need to add 'topan4dd.online' to ALLOWED_HOSTS.
Traceback (most recent call last):
  File "/opt/mcads/app/venv/lib/python3.10/site-packages/asgiref/sync.py", line 489, in thread_handler
    raise exc_info[1]
  File "/opt/mcads/app/venv/lib/python3.10/site-packages/django/core/handlers/exception.py", line 42, in inner
    response = await get_response(request)
  File "/opt/mcads/app/venv/lib/python3.10/site-packages/django/utils/deprecation.py", line 132, in __acall__
    response = await sync_to_async(
  File "/opt/mcads/app/venv/lib/python3.10/site-packages/asgiref/sync.py", line 439, in __call__
    ret = await asyncio.shield(exec_coro)
  File "/usr/lib/python3.10/concurrent/futures/thread.py", line 58, in run
    result = self.fn(*self.args, **self.kwargs)
  File "/opt/mcads/app/venv/lib/python3.10/site-packages/asgiref/sync.py", line 493, in thread_handler
    return func(*args, **kwargs)
  File "/opt/mcads/app/venv/lib/python3.10/site-packages/django/middleware/common.py", line 48, in process_request
    host = request.get_host()
  File "/opt/mcads/app/venv/lib/python3.10/site-packages/django/http/request.py", line 202, in get_host
    raise DisallowedHost(msg)
django.core.exceptions.DisallowedHost: Invalid HTTP_HOST header: 'topan4dd.online'. You may need to add 'topan4dd.online' to ALLOWED_HOSTS.
ERROR 2025-07-21 18:45:23,132 log 15513 140446282012224 Invalid HTTP_HOST header: 'topan4dd.online'. You may need to add 'topan4dd.online' to ALLOWED_HOSTS.
Traceback (most recent call last):
  File "/opt/mcads/app/venv/lib/python3.10/site-packages/asgiref/sync.py", line 489, in thread_handler
    raise exc_info[1]
  File "/opt/mcads/app/venv/lib/python3.10/site-packages/django/core/handlers/exception.py", line 42, in inner
    response = await get_response(request)
  File "/opt/mcads/app/venv/lib/python3.10/site-packages/django/utils/deprecation.py", line 132, in __acall__
    response = await sync_to_async(
  File "/opt/mcads/app/venv/lib/python3.10/site-packages/asgiref/sync.py", line 439, in __call__
    ret = await asyncio.shield(exec_coro)
  File "/usr/lib/python3.10/concurrent/futures/thread.py", line 58, in run
    result = self.fn(*self.args, **self.kwargs)
  File "/opt/mcads/app/venv/lib/python3.10/site-packages/asgiref/sync.py", line 493, in thread_handler
    return func(*args, **kwargs)
  File "/opt/mcads/app/venv/lib/python3.10/site-packages/django/middleware/common.py", line 48, in process_request
    host = request.get_host()
  File "/opt/mcads/app/venv/lib/python3.10/site-packages/django/http/request.py", line 202, in get_host
    raise DisallowedHost(msg)
django.core.exceptions.DisallowedHost: Invalid HTTP_HOST header: 'topan4dd.online'. You may need to add 'topan4dd.online' to ALLOWED_HOSTS.
ERROR 2025-07-21 18:45:23,540 log 15513 140446290404928 Invalid HTTP_HOST header: 'topan4dd.online'. You may need to add 'topan4dd.online' to ALLOWED_HOSTS.
Traceback (most recent call last):
  File "/opt/mcads/app/venv/lib/python3.10/site-packages/asgiref/sync.py", line 489, in thread_handler
    raise exc_info[1]
  File "/opt/mcads/app/venv/lib/python3.10/site-packages/django/core/handlers/exception.py", line 42, in inner
    response = await get_response(request)
  File "/opt/mcads/app/venv/lib/python3.10/site-packages/django/utils/deprecation.py", line 132, in __acall__
    response = await sync_to_async(
  File "/opt/mcads/app/venv/lib/python3.10/site-packages/asgiref/sync.py", line 439, in __call__
    ret = await asyncio.shield(exec_coro)
  File "/usr/lib/python3.10/concurrent/futures/thread.py", line 58, in run
    result = self.fn(*self.args, **self.kwargs)
  File "/opt/mcads/app/venv/lib/python3.10/site-packages/asgiref/sync.py", line 493, in thread_handler
    return func(*args, **kwargs)
  File "/opt/mcads/app/venv/lib/python3.10/site-packages/django/middleware/common.py", line 48, in process_request
    host = request.get_host()
  File "/opt/mcads/app/venv/lib/python3.10/site-packages/django/http/request.py", line 202, in get_host
    raise DisallowedHost(msg)
django.core.exceptions.DisallowedHost: Invalid HTTP_HOST header: 'topan4dd.online'. You may need to add 'topan4dd.online' to ALLOWED_HOSTS.
ERROR 2025-07-21 18:45:23,750 log 15513 140445749335616 Invalid HTTP_HOST header: 'topan4dd.online'. You may need to add 'topan4dd.online' to ALLOWED_HOSTS.
Traceback (most recent call last):
  File "/opt/mcads/app/venv/lib/python3.10/site-packages/asgiref/sync.py", line 489, in thread_handler
    raise exc_info[1]
  File "/opt/mcads/app/venv/lib/python3.10/site-packages/django/core/handlers/exception.py", line 42, in inner
    response = await get_response(request)
  File "/opt/mcads/app/venv/lib/python3.10/site-packages/django/utils/deprecation.py", line 132, in __acall__
    response = await sync_to_async(
  File "/opt/mcads/app/venv/lib/python3.10/site-packages/asgiref/sync.py", line 439, in __call__
    ret = await asyncio.shield(exec_coro)
  File "/usr/lib/python3.10/concurrent/futures/thread.py", line 58, in run
    result = self.fn(*self.args, **self.kwargs)
  File "/opt/mcads/app/venv/lib/python3.10/site-packages/asgiref/sync.py", line 493, in thread_handler
    return func(*args, **kwargs)
  File "/opt/mcads/app/venv/lib/python3.10/site-packages/django/middleware/common.py", line 48, in process_request
    host = request.get_host()
  File "/opt/mcads/app/venv/lib/python3.10/site-packages/django/http/request.py", line 202, in get_host
    raise DisallowedHost(msg)
django.core.exceptions.DisallowedHost: Invalid HTTP_HOST header: 'topan4dd.online'. You may need to add 'topan4dd.online' to ALLOWED_HOSTS.
ERROR 2025-07-21 18:45:24,481 log 15513 140446282012224 Invalid HTTP_HOST header: 'topan4dd.online'. You may need to add 'topan4dd.online' to ALLOWED_HOSTS.
Traceback (most recent call last):
  File "/opt/mcads/app/venv/lib/python3.10/site-packages/asgiref/sync.py", line 489, in thread_handler
    raise exc_info[1]
  File "/opt/mcads/app/venv/lib/python3.10/site-packages/django/core/handlers/exception.py", line 42, in inner
    response = await get_response(request)
  File "/opt/mcads/app/venv/lib/python3.10/site-packages/django/utils/deprecation.py", line 132, in __acall__
    response = await sync_to_async(
  File "/opt/mcads/app/venv/lib/python3.10/site-packages/asgiref/sync.py", line 439, in __call__
    ret = await asyncio.shield(exec_coro)
  File "/usr/lib/python3.10/concurrent/futures/thread.py", line 58, in run
    result = self.fn(*self.args, **self.kwargs)
  File "/opt/mcads/app/venv/lib/python3.10/site-packages/asgiref/sync.py", line 493, in thread_handler
    return func(*args, **kwargs)
  File "/opt/mcads/app/venv/lib/python3.10/site-packages/django/middleware/common.py", line 48, in process_request
    host = request.get_host()
  File "/opt/mcads/app/venv/lib/python3.10/site-packages/django/http/request.py", line 202, in get_host
    raise DisallowedHost(msg)
django.core.exceptions.DisallowedHost: Invalid HTTP_HOST header: 'topan4dd.online'. You may need to add 'topan4dd.online' to ALLOWED_HOSTS.
ERROR 2025-07-21 18:45:25,099 log 15513 140446256834112 Invalid HTTP_HOST header: 'topan4dd.online'. You may need to add 'topan4dd.online' to ALLOWED_HOSTS.
Traceback (most recent call last):
  File "/opt/mcads/app/venv/lib/python3.10/site-packages/asgiref/sync.py", line 489, in thread_handler
    raise exc_info[1]
  File "/opt/mcads/app/venv/lib/python3.10/site-packages/django/core/handlers/exception.py", line 42, in inner
    response = await get_response(request)
  File "/opt/mcads/app/venv/lib/python3.10/site-packages/django/utils/deprecation.py", line 132, in __acall__
    response = await sync_to_async(
  File "/opt/mcads/app/venv/lib/python3.10/site-packages/asgiref/sync.py", line 439, in __call__
    ret = await asyncio.shield(exec_coro)
  File "/usr/lib/python3.10/concurrent/futures/thread.py", line 58, in run
    result = self.fn(*self.args, **self.kwargs)
  File "/opt/mcads/app/venv/lib/python3.10/site-packages/asgiref/sync.py", line 493, in thread_handler
    return func(*args, **kwargs)
  File "/opt/mcads/app/venv/lib/python3.10/site-packages/django/middleware/common.py", line 48, in process_request
    host = request.get_host()
  File "/opt/mcads/app/venv/lib/python3.10/site-packages/django/http/request.py", line 202, in get_host
    raise DisallowedHost(msg)
django.core.exceptions.DisallowedHost: Invalid HTTP_HOST header: 'topan4dd.online'. You may need to add 'topan4dd.online' to ALLOWED_HOSTS.
ERROR 2025-07-21 18:45:25,315 log 15513 140445749335616 Invalid HTTP_HOST header: 'topan4dd.online'. You may need to add 'topan4dd.online' to ALLOWED_HOSTS.
Traceback (most recent call last):
  File "/opt/mcads/app/venv/lib/python3.10/site-packages/asgiref/sync.py", line 489, in thread_handler
    raise exc_info[1]
  File "/opt/mcads/app/venv/lib/python3.10/site-packages/django/core/handlers/exception.py", line 42, in inner
    response = await get_response(request)
  File "/opt/mcads/app/venv/lib/python3.10/site-packages/django/utils/deprecation.py", line 132, in __acall__
    response = await sync_to_async(
  File "/opt/mcads/app/venv/lib/python3.10/site-packages/asgiref/sync.py", line 439, in __call__
    ret = await asyncio.shield(exec_coro)
  File "/usr/lib/python3.10/concurrent/futures/thread.py", line 58, in run
    result = self.fn(*self.args, **self.kwargs)
  File "/opt/mcads/app/venv/lib/python3.10/site-packages/asgiref/sync.py", line 493, in thread_handler
    return func(*args, **kwargs)
  File "/opt/mcads/app/venv/lib/python3.10/site-packages/django/middleware/common.py", line 48, in process_request
    host = request.get_host()
  File "/opt/mcads/app/venv/lib/python3.10/site-packages/django/http/request.py", line 202, in get_host
    raise DisallowedHost(msg)
django.core.exceptions.DisallowedHost: Invalid HTTP_HOST header: 'topan4dd.online'. You may need to add 'topan4dd.online' to ALLOWED_HOSTS.
ERROR 2025-07-21 18:45:26,158 log 15513 140446282012224 Invalid HTTP_HOST header: 'topan4dd.online'. You may need to add 'topan4dd.online' to ALLOWED_HOSTS.
Traceback (most recent call last):
  File "/opt/mcads/app/venv/lib/python3.10/site-packages/asgiref/sync.py", line 489, in thread_handler
    raise exc_info[1]
  File "/opt/mcads/app/venv/lib/python3.10/site-packages/django/core/handlers/exception.py", line 42, in inner
    response = await get_response(request)
  File "/opt/mcads/app/venv/lib/python3.10/site-packages/django/utils/deprecation.py", line 132, in __acall__
    response = await sync_to_async(
  File "/opt/mcads/app/venv/lib/python3.10/site-packages/asgiref/sync.py", line 439, in __call__
    ret = await asyncio.shield(exec_coro)
  File "/usr/lib/python3.10/concurrent/futures/thread.py", line 58, in run
    result = self.fn(*self.args, **self.kwargs)
  File "/opt/mcads/app/venv/lib/python3.10/site-packages/asgiref/sync.py", line 493, in thread_handler
    return func(*args, **kwargs)
  File "/opt/mcads/app/venv/lib/python3.10/site-packages/django/middleware/common.py", line 48, in process_request
    host = request.get_host()
  File "/opt/mcads/app/venv/lib/python3.10/site-packages/django/http/request.py", line 202, in get_host
    raise DisallowedHost(msg)
django.core.exceptions.DisallowedHost: Invalid HTTP_HOST header: 'topan4dd.online'. You may need to add 'topan4dd.online' to ALLOWED_HOSTS.
ERROR 2025-07-21 18:45:26,363 log 15513 140446290404928 Invalid HTTP_HOST header: 'topan4dd.online'. You may need to add 'topan4dd.online' to ALLOWED_HOSTS.
Traceback (most recent call last):
  File "/opt/mcads/app/venv/lib/python3.10/site-packages/asgiref/sync.py", line 489, in thread_handler
    raise exc_info[1]
  File "/opt/mcads/app/venv/lib/python3.10/site-packages/django/core/handlers/exception.py", line 42, in inner
    response = await get_response(request)
  File "/opt/mcads/app/venv/lib/python3.10/site-packages/django/utils/deprecation.py", line 132, in __acall__
    response = await sync_to_async(
  File "/opt/mcads/app/venv/lib/python3.10/site-packages/asgiref/sync.py", line 439, in __call__
    ret = await asyncio.shield(exec_coro)
  File "/usr/lib/python3.10/concurrent/futures/thread.py", line 58, in run
    result = self.fn(*self.args, **self.kwargs)
  File "/opt/mcads/app/venv/lib/python3.10/site-packages/asgiref/sync.py", line 493, in thread_handler
    return func(*args, **kwargs)
  File "/opt/mcads/app/venv/lib/python3.10/site-packages/django/middleware/common.py", line 48, in process_request
    host = request.get_host()
  File "/opt/mcads/app/venv/lib/python3.10/site-packages/django/http/request.py", line 202, in get_host
    raise DisallowedHost(msg)
django.core.exceptions.DisallowedHost: Invalid HTTP_HOST header: 'topan4dd.online'. You may need to add 'topan4dd.online' to ALLOWED_HOSTS.
ERROR 2025-07-21 18:45:27,404 log 15513 140446256834112 Invalid HTTP_HOST header: 'topan4dd.online'. You may need to add 'topan4dd.online' to ALLOWED_HOSTS.
Traceback (most recent call last):
  File "/opt/mcads/app/venv/lib/python3.10/site-packages/asgiref/sync.py", line 489, in thread_handler
    raise exc_info[1]
  File "/opt/mcads/app/venv/lib/python3.10/site-packages/django/core/handlers/exception.py", line 42, in inner
    response = await get_response(request)
  File "/opt/mcads/app/venv/lib/python3.10/site-packages/django/utils/deprecation.py", line 132, in __acall__
    response = await sync_to_async(
  File "/opt/mcads/app/venv/lib/python3.10/site-packages/asgiref/sync.py", line 439, in __call__
    ret = await asyncio.shield(exec_coro)
  File "/usr/lib/python3.10/concurrent/futures/thread.py", line 58, in run
    result = self.fn(*self.args, **self.kwargs)
  File "/opt/mcads/app/venv/lib/python3.10/site-packages/asgiref/sync.py", line 493, in thread_handler
    return func(*args, **kwargs)
  File "/opt/mcads/app/venv/lib/python3.10/site-packages/django/middleware/common.py", line 48, in process_request
    host = request.get_host()
  File "/opt/mcads/app/venv/lib/python3.10/site-packages/django/http/request.py", line 202, in get_host
    raise DisallowedHost(msg)
django.core.exceptions.DisallowedHost: Invalid HTTP_HOST header: 'topan4dd.online'. You may need to add 'topan4dd.online' to ALLOWED_HOSTS.
ERROR 2025-07-21 18:45:27,821 log 15513 140445749335616 Invalid HTTP_HOST header: 'topan4dd.online'. You may need to add 'topan4dd.online' to ALLOWED_HOSTS.
Traceback (most recent call last):
  File "/opt/mcads/app/venv/lib/python3.10/site-packages/asgiref/sync.py", line 489, in thread_handler
    raise exc_info[1]
  File "/opt/mcads/app/venv/lib/python3.10/site-packages/django/core/handlers/exception.py", line 42, in inner
    response = await get_response(request)
  File "/opt/mcads/app/venv/lib/python3.10/site-packages/django/utils/deprecation.py", line 132, in __acall__
    response = await sync_to_async(
  File "/opt/mcads/app/venv/lib/python3.10/site-packages/asgiref/sync.py", line 439, in __call__
    ret = await asyncio.shield(exec_coro)
  File "/usr/lib/python3.10/concurrent/futures/thread.py", line 58, in run
    result = self.fn(*self.args, **self.kwargs)
  File "/opt/mcads/app/venv/lib/python3.10/site-packages/asgiref/sync.py", line 493, in thread_handler
    return func(*args, **kwargs)
  File "/opt/mcads/app/venv/lib/python3.10/site-packages/django/middleware/common.py", line 48, in process_request
    host = request.get_host()
  File "/opt/mcads/app/venv/lib/python3.10/site-packages/django/http/request.py", line 202, in get_host
    raise DisallowedHost(msg)
django.core.exceptions.DisallowedHost: Invalid HTTP_HOST header: 'topan4dd.online'. You may need to add 'topan4dd.online' to ALLOWED_HOSTS.
ERROR 2025-07-21 18:45:28,338 log 15513 140446282012224 Invalid HTTP_HOST header: 'topan4dd.online'. You may need to add 'topan4dd.online' to ALLOWED_HOSTS.
Traceback (most recent call last):
  File "/opt/mcads/app/venv/lib/python3.10/site-packages/asgiref/sync.py", line 489, in thread_handler
    raise exc_info[1]
  File "/opt/mcads/app/venv/lib/python3.10/site-packages/django/core/handlers/exception.py", line 42, in inner
    response = await get_response(request)
  File "/opt/mcads/app/venv/lib/python3.10/site-packages/django/utils/deprecation.py", line 132, in __acall__
    response = await sync_to_async(
  File "/opt/mcads/app/venv/lib/python3.10/site-packages/asgiref/sync.py", line 439, in __call__
    ret = await asyncio.shield(exec_coro)
  File "/usr/lib/python3.10/concurrent/futures/thread.py", line 58, in run
    result = self.fn(*self.args, **self.kwargs)
  File "/opt/mcads/app/venv/lib/python3.10/site-packages/asgiref/sync.py", line 493, in thread_handler
    return func(*args, **kwargs)
  File "/opt/mcads/app/venv/lib/python3.10/site-packages/django/middleware/common.py", line 48, in process_request
    host = request.get_host()
  File "/opt/mcads/app/venv/lib/python3.10/site-packages/django/http/request.py", line 202, in get_host
    raise DisallowedHost(msg)
django.core.exceptions.DisallowedHost: Invalid HTTP_HOST header: 'topan4dd.online'. You may need to add 'topan4dd.online' to ALLOWED_HOSTS.
ERROR 2025-07-21 18:45:28,758 log 15513 140446290404928 Invalid HTTP_HOST header: 'topan4dd.online'. You may need to add 'topan4dd.online' to ALLOWED_HOSTS.
Traceback (most recent call last):
  File "/opt/mcads/app/venv/lib/python3.10/site-packages/asgiref/sync.py", line 489, in thread_handler
    raise exc_info[1]
  File "/opt/mcads/app/venv/lib/python3.10/site-packages/django/core/handlers/exception.py", line 42, in inner
    response = await get_response(request)
  File "/opt/mcads/app/venv/lib/python3.10/site-packages/django/utils/deprecation.py", line 132, in __acall__
    response = await sync_to_async(
  File "/opt/mcads/app/venv/lib/python3.10/site-packages/asgiref/sync.py", line 439, in __call__
    ret = await asyncio.shield(exec_coro)
  File "/usr/lib/python3.10/concurrent/futures/thread.py", line 58, in run
    result = self.fn(*self.args, **self.kwargs)
  File "/opt/mcads/app/venv/lib/python3.10/site-packages/asgiref/sync.py", line 493, in thread_handler
    return func(*args, **kwargs)
  File "/opt/mcads/app/venv/lib/python3.10/site-packages/django/middleware/common.py", line 48, in process_request
    host = request.get_host()
  File "/opt/mcads/app/venv/lib/python3.10/site-packages/django/http/request.py", line 202, in get_host
    raise DisallowedHost(msg)
django.core.exceptions.DisallowedHost: Invalid HTTP_HOST header: 'topan4dd.online'. You may need to add 'topan4dd.online' to ALLOWED_HOSTS.
ERROR 2025-07-21 18:45:28,964 log 15513 140445749335616 Invalid HTTP_HOST header: 'topan4dd.online'. You may need to add 'topan4dd.online' to ALLOWED_HOSTS.
Traceback (most recent call last):
  File "/opt/mcads/app/venv/lib/python3.10/site-packages/asgiref/sync.py", line 489, in thread_handler
    raise exc_info[1]
  File "/opt/mcads/app/venv/lib/python3.10/site-packages/django/core/handlers/exception.py", line 42, in inner
    response = await get_response(request)
  File "/opt/mcads/app/venv/lib/python3.10/site-packages/django/utils/deprecation.py", line 132, in __acall__
    response = await sync_to_async(
  File "/opt/mcads/app/venv/lib/python3.10/site-packages/asgiref/sync.py", line 439, in __call__
    ret = await asyncio.shield(exec_coro)
  File "/usr/lib/python3.10/concurrent/futures/thread.py", line 58, in run
    result = self.fn(*self.args, **self.kwargs)
  File "/opt/mcads/app/venv/lib/python3.10/site-packages/asgiref/sync.py", line 493, in thread_handler
    return func(*args, **kwargs)
  File "/opt/mcads/app/venv/lib/python3.10/site-packages/django/middleware/common.py", line 48, in process_request
    host = request.get_host()
  File "/opt/mcads/app/venv/lib/python3.10/site-packages/django/http/request.py", line 202, in get_host
    raise DisallowedHost(msg)
django.core.exceptions.DisallowedHost: Invalid HTTP_HOST header: 'topan4dd.online'. You may need to add 'topan4dd.online' to ALLOWED_HOSTS.
ERROR 2025-07-21 18:45:29,187 log 15513 140446282012224 Invalid HTTP_HOST header: 'topan4dd.online'. You may need to add 'topan4dd.online' to ALLOWED_HOSTS.
Traceback (most recent call last):
  File "/opt/mcads/app/venv/lib/python3.10/site-packages/asgiref/sync.py", line 489, in thread_handler
    raise exc_info[1]
  File "/opt/mcads/app/venv/lib/python3.10/site-packages/django/core/handlers/exception.py", line 42, in inner
    response = await get_response(request)
  File "/opt/mcads/app/venv/lib/python3.10/site-packages/django/utils/deprecation.py", line 132, in __acall__
    response = await sync_to_async(
  File "/opt/mcads/app/venv/lib/python3.10/site-packages/asgiref/sync.py", line 439, in __call__
    ret = await asyncio.shield(exec_coro)
  File "/usr/lib/python3.10/concurrent/futures/thread.py", line 58, in run
    result = self.fn(*self.args, **self.kwargs)
  File "/opt/mcads/app/venv/lib/python3.10/site-packages/asgiref/sync.py", line 493, in thread_handler
    return func(*args, **kwargs)
  File "/opt/mcads/app/venv/lib/python3.10/site-packages/django/middleware/common.py", line 48, in process_request
    host = request.get_host()
  File "/opt/mcads/app/venv/lib/python3.10/site-packages/django/http/request.py", line 202, in get_host
    raise DisallowedHost(msg)
django.core.exceptions.DisallowedHost: Invalid HTTP_HOST header: 'topan4dd.online'. You may need to add 'topan4dd.online' to ALLOWED_HOSTS.
ERROR 2025-07-21 18:45:29,608 log 15513 140446290404928 Invalid HTTP_HOST header: 'topan4dd.online'. You may need to add 'topan4dd.online' to ALLOWED_HOSTS.
Traceback (most recent call last):
  File "/opt/mcads/app/venv/lib/python3.10/site-packages/asgiref/sync.py", line 489, in thread_handler
    raise exc_info[1]
  File "/opt/mcads/app/venv/lib/python3.10/site-packages/django/core/handlers/exception.py", line 42, in inner
    response = await get_response(request)
  File "/opt/mcads/app/venv/lib/python3.10/site-packages/django/utils/deprecation.py", line 132, in __acall__
    response = await sync_to_async(
  File "/opt/mcads/app/venv/lib/python3.10/site-packages/asgiref/sync.py", line 439, in __call__
    ret = await asyncio.shield(exec_coro)
  File "/usr/lib/python3.10/concurrent/futures/thread.py", line 58, in run
    result = self.fn(*self.args, **self.kwargs)
  File "/opt/mcads/app/venv/lib/python3.10/site-packages/asgiref/sync.py", line 493, in thread_handler
    return func(*args, **kwargs)
  File "/opt/mcads/app/venv/lib/python3.10/site-packages/django/middleware/common.py", line 48, in process_request
    host = request.get_host()
  File "/opt/mcads/app/venv/lib/python3.10/site-packages/django/http/request.py", line 202, in get_host
    raise DisallowedHost(msg)
django.core.exceptions.DisallowedHost: Invalid HTTP_HOST header: 'topan4dd.online'. You may need to add 'topan4dd.online' to ALLOWED_HOSTS.
ERROR 2025-07-21 18:45:30,009 log 15513 140446256834112 Invalid HTTP_HOST header: 'topan4dd.online'. You may need to add 'topan4dd.online' to ALLOWED_HOSTS.
Traceback (most recent call last):
  File "/opt/mcads/app/venv/lib/python3.10/site-packages/asgiref/sync.py", line 489, in thread_handler
    raise exc_info[1]
  File "/opt/mcads/app/venv/lib/python3.10/site-packages/django/core/handlers/exception.py", line 42, in inner
    response = await get_response(request)
  File "/opt/mcads/app/venv/lib/python3.10/site-packages/django/utils/deprecation.py", line 132, in __acall__
    response = await sync_to_async(
  File "/opt/mcads/app/venv/lib/python3.10/site-packages/asgiref/sync.py", line 439, in __call__
    ret = await asyncio.shield(exec_coro)
  File "/usr/lib/python3.10/concurrent/futures/thread.py", line 58, in run
    result = self.fn(*self.args, **self.kwargs)
  File "/opt/mcads/app/venv/lib/python3.10/site-packages/asgiref/sync.py", line 493, in thread_handler
    return func(*args, **kwargs)
  File "/opt/mcads/app/venv/lib/python3.10/site-packages/django/middleware/common.py", line 48, in process_request
    host = request.get_host()
  File "/opt/mcads/app/venv/lib/python3.10/site-packages/django/http/request.py", line 202, in get_host
    raise DisallowedHost(msg)
django.core.exceptions.DisallowedHost: Invalid HTTP_HOST header: 'topan4dd.online'. You may need to add 'topan4dd.online' to ALLOWED_HOSTS.
ERROR 2025-07-21 18:45:30,430 log 15513 140445749335616 Invalid HTTP_HOST header: 'topan4dd.online'. You may need to add 'topan4dd.online' to ALLOWED_HOSTS.
Traceback (most recent call last):
  File "/opt/mcads/app/venv/lib/python3.10/site-packages/asgiref/sync.py", line 489, in thread_handler
    raise exc_info[1]
  File "/opt/mcads/app/venv/lib/python3.10/site-packages/django/core/handlers/exception.py", line 42, in inner
    response = await get_response(request)
  File "/opt/mcads/app/venv/lib/python3.10/site-packages/django/utils/deprecation.py", line 132, in __acall__
    response = await sync_to_async(
  File "/opt/mcads/app/venv/lib/python3.10/site-packages/asgiref/sync.py", line 439, in __call__
    ret = await asyncio.shield(exec_coro)
  File "/usr/lib/python3.10/concurrent/futures/thread.py", line 58, in run
    result = self.fn(*self.args, **self.kwargs)
  File "/opt/mcads/app/venv/lib/python3.10/site-packages/asgiref/sync.py", line 493, in thread_handler
    return func(*args, **kwargs)
  File "/opt/mcads/app/venv/lib/python3.10/site-packages/django/middleware/common.py", line 48, in process_request
    host = request.get_host()
  File "/opt/mcads/app/venv/lib/python3.10/site-packages/django/http/request.py", line 202, in get_host
    raise DisallowedHost(msg)
django.core.exceptions.DisallowedHost: Invalid HTTP_HOST header: 'topan4dd.online'. You may need to add 'topan4dd.online' to ALLOWED_HOSTS.
ERROR 2025-07-21 18:45:30,841 log 15513 140446282012224 Invalid HTTP_HOST header: 'topan4dd.online'. You may need to add 'topan4dd.online' to ALLOWED_HOSTS.
Traceback (most recent call last):
  File "/opt/mcads/app/venv/lib/python3.10/site-packages/asgiref/sync.py", line 489, in thread_handler
    raise exc_info[1]
  File "/opt/mcads/app/venv/lib/python3.10/site-packages/django/core/handlers/exception.py", line 42, in inner
    response = await get_response(request)
  File "/opt/mcads/app/venv/lib/python3.10/site-packages/django/utils/deprecation.py", line 132, in __acall__
    response = await sync_to_async(
  File "/opt/mcads/app/venv/lib/python3.10/site-packages/asgiref/sync.py", line 439, in __call__
    ret = await asyncio.shield(exec_coro)
  File "/usr/lib/python3.10/concurrent/futures/thread.py", line 58, in run
    result = self.fn(*self.args, **self.kwargs)
  File "/opt/mcads/app/venv/lib/python3.10/site-packages/asgiref/sync.py", line 493, in thread_handler
    return func(*args, **kwargs)
  File "/opt/mcads/app/venv/lib/python3.10/site-packages/django/middleware/common.py", line 48, in process_request
    host = request.get_host()
  File "/opt/mcads/app/venv/lib/python3.10/site-packages/django/http/request.py", line 202, in get_host
    raise DisallowedHost(msg)
django.core.exceptions.DisallowedHost: Invalid HTTP_HOST header: 'topan4dd.online'. You may need to add 'topan4dd.online' to ALLOWED_HOSTS.
ERROR 2025-07-21 18:45:31,267 log 15513 140446290404928 Invalid HTTP_HOST header: 'topan4dd.online'. You may need to add 'topan4dd.online' to ALLOWED_HOSTS.
Traceback (most recent call last):
  File "/opt/mcads/app/venv/lib/python3.10/site-packages/asgiref/sync.py", line 489, in thread_handler
    raise exc_info[1]
  File "/opt/mcads/app/venv/lib/python3.10/site-packages/django/core/handlers/exception.py", line 42, in inner
    response = await get_response(request)
  File "/opt/mcads/app/venv/lib/python3.10/site-packages/django/utils/deprecation.py", line 132, in __acall__
    response = await sync_to_async(
  File "/opt/mcads/app/venv/lib/python3.10/site-packages/asgiref/sync.py", line 439, in __call__
    ret = await asyncio.shield(exec_coro)
  File "/usr/lib/python3.10/concurrent/futures/thread.py", line 58, in run
    result = self.fn(*self.args, **self.kwargs)
  File "/opt/mcads/app/venv/lib/python3.10/site-packages/asgiref/sync.py", line 493, in thread_handler
    return func(*args, **kwargs)
  File "/opt/mcads/app/venv/lib/python3.10/site-packages/django/middleware/common.py", line 48, in process_request
    host = request.get_host()
  File "/opt/mcads/app/venv/lib/python3.10/site-packages/django/http/request.py", line 202, in get_host
    raise DisallowedHost(msg)
django.core.exceptions.DisallowedHost: Invalid HTTP_HOST header: 'topan4dd.online'. You may need to add 'topan4dd.online' to ALLOWED_HOSTS.
ERROR 2025-07-21 18:45:31,713 log 15513 140446256834112 Invalid HTTP_HOST header: 'topan4dd.online'. You may need to add 'topan4dd.online' to ALLOWED_HOSTS.
Traceback (most recent call last):
  File "/opt/mcads/app/venv/lib/python3.10/site-packages/asgiref/sync.py", line 489, in thread_handler
    raise exc_info[1]
  File "/opt/mcads/app/venv/lib/python3.10/site-packages/django/core/handlers/exception.py", line 42, in inner
    response = await get_response(request)
  File "/opt/mcads/app/venv/lib/python3.10/site-packages/django/utils/deprecation.py", line 132, in __acall__
    response = await sync_to_async(
  File "/opt/mcads/app/venv/lib/python3.10/site-packages/asgiref/sync.py", line 439, in __call__
    ret = await asyncio.shield(exec_coro)
  File "/usr/lib/python3.10/concurrent/futures/thread.py", line 58, in run
    result = self.fn(*self.args, **self.kwargs)
  File "/opt/mcads/app/venv/lib/python3.10/site-packages/asgiref/sync.py", line 493, in thread_handler
    return func(*args, **kwargs)
  File "/opt/mcads/app/venv/lib/python3.10/site-packages/django/middleware/common.py", line 48, in process_request
    host = request.get_host()
  File "/opt/mcads/app/venv/lib/python3.10/site-packages/django/http/request.py", line 202, in get_host
    raise DisallowedHost(msg)
django.core.exceptions.DisallowedHost: Invalid HTTP_HOST header: 'topan4dd.online'. You may need to add 'topan4dd.online' to ALLOWED_HOSTS.
